Workbook
Name BLOCKMOD: Vitals!$J$28
Name FOCUSREGEN: #REF!
Name HEAD: Vitals!$E$3:$G$4
Name Combat: Social!$A$1:$A$1000
Name WEIGHT: #REF!
Name APTMOD: Main!$K$6
Name INT: Main!$F$7
Name LEFTUPPERARM: Vitals!$I$8
Name FOCUS: #REF!
Name REGENMOD: Main!$L$4
Name AGE: Main!$E$14
Name LIFESPAN: Main!$D$14
Name WEIGHT: #REF!
Name Combat: Negative!$A$1:$A$1000
Name SkillsKV: Skills!$R$21
Name BEAUTYMOD: Skills!$X$65
Name CON: Main!$F$6
Name Combat: 'Super Tech'!$A$1:$A$1000
Name LEFTUPPERLEG: Vitals!$G$13:$G$14
Name TOUGHNESS: Main!$H$4
Name PORTRAITURL: 'Sheet Settings'!$D$2
Name CHA: Main!$F$9
Name LEFTLOWERARM: Vitals!$I$11
Name RIGHTLOWERARM: Vitals!$C$11
Name RIGHTUPPERARM: #REF!
Name Combat: Learning!$A$1:$A$1000
Name TOTALKV: Main!$C$2:$D$2
Name REFLEXES: #REF!
Name FOCUSMOD: Main!$K$8
Name KARMA: Main!$J$19:$J$20
Name Combat: Magic!$A$1:$A$1000
Name DEX: Main!$F$5
Name Combat: Combat!$A$1:$A$1000
Name WIS: Main!$F$8
Name SPEEDMOD: Main!$L$6
Name RIGHTLOWERLEG: Vitals!$E$18
Name BEAUTY: Main!$F$12
Name LEFTLOWERLEG: Vitals!$G$18
Name COUNTKV: #REF!
Name Combat: Supernatural!$A$1:$A$1000
Name CHEST: Vitals!$E$8:$G$9
Name MAXFOCUS: #REF!
Name Combat: Utility!$A$1:$A$1000
Name RESISTMOD: Main!$K$4
Name Combat: Natural!$A$1:$A$1000
Name WEIGHT: Inventory!$AI$38
Name STR: Main!$F$4
Name WOUNDSTREATED: Vitals!$I$15
Name WEIGHT: #REF!
Name RIGHTUPPERLEG: Vitals!$E$13:$E$14
Name STRAIN: #REF!

Sheet Main
B2: Irsos | C2: {='Sheet Settings'!D5 + Skills!R21+(SUM(F4:F6))*4+(SUM(F7:F9))*8+SUM(Exploits!G3:G52)+vlookup(D12,indirect("SEEDDATA!A:C"),2,false)+ IF(BEAUTY = 1,-12, IF(BEAUTY = 2,-8, IF(BEAUTY = 3,-4, IF(BEAUTY = 4,-4, IF(BEAUTY = 5,0, IF(BEAUTY = 6,+0, IF(BEAUTY = 7,+4, IF(BEAUTY = 8,+4, IF(BEAUTY = 9,+8, IF(BEAUTY = 10,+12,))))))))))+ IF(G2 = "1 - Destitute", -80, IF(G2 = "2 - Impoverished",-60, IF(G2 = "3 - Poor",-40, IF(G2 = "4 - Lower Middle Class",-20, IF(G2 = "5 - Middle Class",0, IF(G2 = "6 - Upper Middle Class",20, IF(G2 = "7 - Upper Class",40, IF(G2 = "8 - Rich",60, IF(G2 = "9 - Super Rich",80, IF(G2 = "10 - Elite",100, 0))))))))))} -> 508 | E2: 1 - Primitive | G2: 1 - Destitute | J2: TRUE | K2: TRUE | L2: TRUE
B3: =IMAGE(PORTRAITURL,1) -> #REF! | C3: KARMIC LEVEL | E3: TECH LEVEL | G3: WEALTH LEVEL
C4: STRENGTH | E4: 14 | F4: =E4-IF((LIFESPAN) = "2 - Normal", IF((AGE)<30,0, IF(AGE < 40,1, IF(AGE < 50,3, IF(AGE < 60,6, IF(AGE < 70,10, IF(AGE < 80,15, IF(AGE < 90,21, IF(AGE < 100,28, IF(AGE < 110,36, IF(AGE < 120,45, IF(AGE < 130,55, IF(AGE < 140,66, IF(AGE < 150,78, IF(AGE < 160,91, IF(AGE < 170,105, IF(AGE < 180,120,136)))))))))))))))), IF((LIFESPAN) = "1 - Short", IF((AGE)<20,0, IF(AGE < 30,1, IF(AGE < 40,3, IF(AGE < 50,6, IF(AGE < 60,10, IF(AGE < 70,15, IF(AGE < 80,21, IF(AGE < 90,28, IF(AGE < 100,36, IF(AGE < 111,45, IF(AGE < 120,55, IF(AGE < 130,66, IF(AGE < 140,78, IF(AGE < 150,91, IF(AGE < 160,105, IF(AGE < 170,120,136)))))))))))))))), IF((LIFESPAN) = "3 - Extended", IF((AGE)<40,0, IF(AGE < 50,1, IF(AGE < 60,3, IF(AGE < 70,6, IF(AGE < 80,10, IF(AGE < 90,15, IF(AGE < 100,21, IF(AGE < 110,28, IF(AGE < 120,36, IF(AGE < 130,45, IF(AGE < 140,55, IF(AGE < 150,66, IF(AGE < 160,78, IF(AGE < 170,91, IF(AGE < 180,105, IF(AGE < 190,120,136)))))))))))))))), IF((LIFESPAN) = "4 - Long", IF((AGE)<50,0, IF(AGE < 60,1, IF(AGE < 70,3, IF(AGE < 80,6, IF(AGE < 90,10, IF(AGE < 100,15, IF(AGE < 110,21, IF(AGE < 120,28, IF(AGE < 130,36, IF(AGE < 140,45, IF(AGE < 150,55, IF(AGE < 160,66, IF(AGE < 170,78, IF(AGE < 180,91, IF(AGE < 190,105, IF(AGE < 200,120,136)))))))))))))))), IF((LIFESPAN) = "5 - Epic", IF((AGE)<80,0, IF(AGE < 90,1, IF(AGE < 100,3, IF(AGE < 110,6, IF(AGE < 120,10, IF(AGE < 130,15, IF(AGE < 140,21, IF(AGE < 150,28, IF(AGE < 160,36, IF(AGE < 170,45, IF(AGE < 180,55, IF(AGE < 190,66, IF(AGE < 200,78, IF(AGE < 210,91, IF(AGE < 220,105, IF(AGE < 230,120,136)))))))))))))))), IF((LIFESPAN) = "6 - Immortal", 0,0)))))) -> 14 | G4: 0 | H4: =MIN(20,(STR)+G4) -> 14 | I4: TOUGHNESS | K4: 20 | L4: 10
C5: DEXTERITY | E5: 15 | F5: =E5-IF((LIFESPAN) = "2 - Normal", IF((AGE)<40,0, IF(AGE < 50,1, IF(AGE < 60,3, IF(AGE < 70,6, IF(AGE < 80,10, IF(AGE < 90,15, IF(AGE < 100,21, IF(AGE < 110,28, IF(AGE < 120,36, IF(AGE < 130,45, IF(AGE < 140,55, IF(AGE < 150,66, IF(AGE < 160,78, IF(AGE < 170,91, IF(AGE < 180,105,120))))))))))))))), IF((LIFESPAN) = "1 - Short", IF((AGE)<30,0, IF(AGE < 40,1, IF(AGE < 50,3, IF(AGE < 60,6, IF(AGE < 70,10, IF(AGE < 80,15, IF(AGE < 90,21, IF(AGE < 100,28, IF(AGE < 110,36, IF(AGE < 120,45, IF(AGE < 130,55, IF(AGE < 140,66, IF(AGE < 150,78, IF(AGE < 160,91, IF(AGE < 170,105, IF(AGE < 180,120,136)))))))))))))))), IF((LIFESPAN) = "3 - Extended", IF((AGE)<50,0, IF(AGE < 60,1, IF(AGE < 70,3, IF(AGE < 80,6, IF(AGE < 90,10, IF(AGE < 100,15, IF(AGE < 110,21, IF(AGE < 120,28, IF(AGE < 130,36, IF(AGE < 140,45, IF(AGE < 150,55, IF(AGE < 160,66, IF(AGE < 170,78, IF(AGE < 180,91, IF(AGE < 190,105,120))))))))))))))), IF((LIFESPAN) = "4 - Long", IF((AGE)<60,0, IF(AGE < 70,1, IF(AGE < 80,3, IF(AGE < 90,6, IF(AGE < 100,10, IF(AGE < 110,15, IF(AGE < 120,21, IF(AGE < 130,28, IF(AGE < 140,36, IF(AGE < 150,45, IF(AGE < 160,55, IF(AGE < 170,66, IF(AGE < 180,78, IF(AGE < 190,91, IF(AGE < 200,105,120))))))))))))))), IF((LIFESPAN) = "5 - Epic", IF((AGE)<90,0, IF(AGE < 100,1, IF(AGE < 110,3, IF(AGE < 120,6, IF(AGE < 130,10, IF(AGE < 140,15, IF(AGE < 150,21, IF(AGE < 160,28, IF(AGE < 170,36, IF(AGE < 180,45, IF(AGE < 190,55, IF(AGE < 200,66, IF(AGE < 210,78, IF(AGE < 220,91, IF(AGE < 230,105,120))))))))))))))), IF((LIFESPAN) = "6 - Immortal", 0,0)))))) -> 15 | G5: 10 | H5: =MIN(20,(DEX)+G5-Vitals!BS30) -> 20 | I5: NIMBLENESS | K5: BASE RESIST | L5: BASE HEALING
C6: CONSTITUTION | E6: 15 | F6: =E6-IF((LIFESPAN) = "2 - Normal", IF((AGE)<50,0, IF(AGE < 60,1, IF(AGE < 70,3, IF(AGE < 80,6, IF(AGE < 90,10, IF(AGE < 100,15, IF(AGE < 110,21, IF(AGE < 120,28, IF(AGE < 130,36, IF(AGE < 140,45, IF(AGE < 150,55, IF(AGE < 160,66, IF(AGE < 170,78, IF(AGE < 180,91,136)))))))))))))), IF((LIFESPAN) = "1 - Short", IF((AGE)<40,0, IF(AGE < 50,1, IF(AGE < 60,3, IF(AGE < 70,6, IF(AGE < 80,10, IF(AGE < 90,15, IF(AGE < 100,21, IF(AGE < 110,28, IF(AGE < 120,36, IF(AGE < 130,45, IF(AGE < 140,55, IF(AGE < 150,66, IF(AGE < 160,78, IF(AGE < 170,91, IF(AGE < 180,105, IF(AGE < 190,120,136)))))))))))))))), IF((LIFESPAN) = "3 - Extended", IF((AGE)<60,0, IF(AGE < 70,1, IF(AGE < 80,3, IF(AGE < 90,6, IF(AGE < 100,10, IF(AGE < 110,15, IF(AGE < 120,21, IF(AGE < 130,28, IF(AGE < 140,36, IF(AGE < 150,45, IF(AGE < 160,55, IF(AGE < 170,66, IF(AGE < 180,78, IF(AGE < 190,91,136)))))))))))))), IF((LIFESPAN) = "4 - Long", IF((AGE)<70,0, IF(AGE < 80,1, IF(AGE < 90,3, IF(AGE < 100,6, IF(AGE < 110,10, IF(AGE < 120,15, IF(AGE < 130,21, IF(AGE < 140,28, IF(AGE < 150,36, IF(AGE < 160,45, IF(AGE < 170,55, IF(AGE < 180,66, IF(AGE < 190,78, IF(AGE < 200,91,120)))))))))))))), IF((LIFESPAN) = "5 - Epic", IF((AGE)<100,0, IF(AGE < 110,1, IF(AGE < 120,3, IF(AGE < 130,6, IF(AGE < 140,10, IF(AGE < 150,15, IF(AGE < 160,21, IF(AGE < 170,28, IF(AGE < 180,36, IF(AGE < 190,45, IF(AGE < 200,55, IF(AGE < 210,66, IF(AGE < 220,78, IF(AGE < 230,91,120)))))))))))))), IF((LIFESPAN) = "6 - Immortal", 0,0)))))) -> 15 | G6: 0 | H6: =MIN(20,(CON)+G6) -> 15 | I6: VIRILITY | K6: 5 | L6: 5
C7: INTELLIGENCE | E7: 17 | F7: =E7-IF((LIFESPAN) = "2 - Normal", IF((AGE)<60,0, IF(AGE < 70,1, IF(AGE < 80,3, IF(AGE < 90,6, IF(AGE < 100,10, IF(AGE < 110,15, IF(AGE < 120,21, IF(AGE < 130,28, IF(AGE < 140,36, IF(AGE < 150,45, IF(AGE < 160,55, IF(AGE < 170,66, IF(AGE < 180,78,105))))))))))))), IF((LIFESPAN) = "1 - Short", IF((AGE)<50,0, IF(AGE < 40,1, IF(AGE < 50,3, IF(AGE < 60,6, IF(AGE < 70,10, IF(AGE < 80,15, IF(AGE < 90,21, IF(AGE < 100,28, IF(AGE < 110,36, IF(AGE < 120,45, IF(AGE < 130,55, IF(AGE < 140,66, IF(AGE < 150,78, IF(AGE < 160,91, IF(AGE < 170,105, IF(AGE < 180,120,136)))))))))))))))), IF((LIFESPAN) = "3 - Extended", IF((AGE)<70,0, IF(AGE < 80,1, IF(AGE < 90,3, IF(AGE < 100,6, IF(AGE < 110,10, IF(AGE < 120,15, IF(AGE < 130,21, IF(AGE < 140,28, IF(AGE < 150,36, IF(AGE < 160,45, IF(AGE < 170,55, IF(AGE < 180,66, IF(AGE < 190,78,136))))))))))))), IF((LIFESPAN) = "4 - Long", IF((AGE)<70,0, IF(AGE < 80,1, IF(AGE < 90,3, IF(AGE < 100,6, IF(AGE < 110,10, IF(AGE < 120,15, IF(AGE < 130,21, IF(AGE < 140,28, IF(AGE < 150,36, IF(AGE < 160,45, IF(AGE < 170,55, IF(AGE < 180,66, IF(AGE < 190,78, IF(AGE < 200,91,120)))))))))))))), IF((LIFESPAN) = "5 - Epic", IF((AGE)<100,0, IF(AGE < 110,1, IF(AGE < 120,3, IF(AGE < 130,6, IF(AGE < 140,10, IF(AGE < 150,15, IF(AGE < 160,21, IF(AGE < 170,28, IF(AGE < 180,36, IF(AGE < 190,45, IF(AGE < 200,55, IF(AGE < 210,66, IF(AGE < 220,78, IF(AGE < 230,91,120)))))))))))))), IF((LIFESPAN) = "6 - Immortal", 0,0)))))) -> 17 | G7: 10 | H7: =MIN(20,(INT)+G7) -> 20 | I7: WIT | K7: BASE APT | L7: SPEED MOD
C8: WISDOM | E8: 16 | F8: =E8-IF((LIFESPAN) = "2 - Normal", IF((AGE)<70,0, IF(AGE < 80,1, IF(AGE < 90,3, IF(AGE < 100,6, IF(AGE < 110,10, IF(AGE < 120,15, IF(AGE < 130,21, IF(AGE < 140,28, IF(AGE < 150,36, IF(AGE < 160,45, IF(AGE < 170,55, IF(AGE < 180,66,105)))))))))))), IF((LIFESPAN) = "1 - Short", IF((AGE)<60,0, IF(AGE < 70,1, IF(AGE < 80,3, IF(AGE < 90,6, IF(AGE < 100,10, IF(AGE < 110,15, IF(AGE < 120,21, IF(AGE < 130,28, IF(AGE < 140,36, IF(AGE < 150,45, IF(AGE < 160,55, IF(AGE < 170,66, IF(AGE < 180,78, IF(AGE < 190,91, IF(AGE < 200,105, IF(AGE < 210,120,136)))))))))))))))), IF((LIFESPAN) = "3 - Extended", IF((AGE)<80,0, IF(AGE < 90,1, IF(AGE < 100,3, IF(AGE < 110,6, IF(AGE < 120,10, IF(AGE < 130,15, IF(AGE < 140,21, IF(AGE < 150,28, IF(AGE < 160,36, IF(AGE < 170,45, IF(AGE < 180,55, IF(AGE < 190,66,136)))))))))))), IF((LIFESPAN) = "4 - Long", IF((AGE)<80,0, IF(AGE < 90,1, IF(AGE < 100,3, IF(AGE < 110,6, IF(AGE < 120,10, IF(AGE < 130,15, IF(AGE < 140,21, IF(AGE < 150,28, IF(AGE < 160,36, IF(AGE < 170,45, IF(AGE < 180,55, IF(AGE < 190,66, IF(AGE < 200,78,120))))))))))))), IF((LIFESPAN) = "5 - Epic", IF((AGE)<110,0, IF(AGE < 120,1, IF(AGE < 130,3, IF(AGE < 140,6, IF(AGE < 150,10, IF(AGE < 160,15, IF(AGE < 170,21, IF(AGE < 180,28, IF(AGE < 190,36, IF(AGE < 200,45, IF(AGE < 210,55, IF(AGE < 220,66, IF(AGE < 230,78,120))))))))))))), IF((LIFESPAN) = "6 - Immortal", 0,0)))))) -> 16 | G8: 10 | H8: =MIN(20,(WIS)+G8) -> 20 | I8: INGENUITY | K8: 500 | L8: 30
C9: CHARISMA | E9: 20 | F9: =E9-IF((LIFESPAN) = "2 - Normal", IF((AGE)<80,0, IF(AGE < 90,1, IF(AGE < 100,3, IF(AGE < 110,6, IF(AGE < 120,10, IF(AGE < 130,15, IF(AGE < 140,21, IF(AGE < 150,28, IF(AGE < 160,36, IF(AGE < 170,45, IF(AGE < 180,55,105))))))))))), IF((LIFESPAN) = "1 - Short", IF((AGE)<70,0, IF(AGE < 80,1, IF(AGE < 90,3, IF(AGE < 100,6, IF(AGE < 110,10, IF(AGE < 120,15, IF(AGE < 130,21, IF(AGE < 140,28, IF(AGE < 150,36, IF(AGE < 160,45, IF(AGE < 170,55, IF(AGE < 180,66, IF(AGE < 190,78, IF(AGE < 200,91, IF(AGE < 210,105, IF(AGE < 220,120,136)))))))))))))))), IF((LIFESPAN) = "3 - Extended", IF((AGE)<90,0, IF(AGE < 100,1, IF(AGE < 110,3, IF(AGE < 120,6, IF(AGE < 130,10, IF(AGE < 140,15, IF(AGE < 150,21, IF(AGE < 160,28, IF(AGE < 170,36, IF(AGE < 180,45, IF(AGE < 190,55,136))))))))))), IF((LIFESPAN) = "4 - Long", IF((AGE)<90,0, IF(AGE < 100,1, IF(AGE < 110,3, IF(AGE < 120,6, IF(AGE < 130,10, IF(AGE < 140,15, IF(AGE < 150,21, IF(AGE < 160,28, IF(AGE < 170,36, IF(AGE < 180,45, IF(AGE < 190,55, IF(AGE < 200,66,120)))))))))))), IF((LIFESPAN) = "5 - Epic", IF((AGE)<120,0, IF(AGE < 130,1, IF(AGE < 140,3, IF(AGE < 150,6, IF(AGE < 160,10, IF(AGE < 170,15, IF(AGE < 180,21, IF(AGE < 190,28, IF(AGE < 200,36, IF(AGE < 210,45, IF(AGE < 220,55, IF(AGE < 230,66,120)))))))))))), IF((LIFESPAN) = "6 - Immortal", 0,0)))))) -> 20 | G9: 10 | H9: =MIN(20,(CHA)+G9) -> 20 | I9: CONVICTION | K9: BASE ENDURANCE | L9: UNARMED MOD
D10: ATTRIBUTES | E10: LEVEL | F10: SCORE | G10: RESIT MODS | H10: RESISTANCES | K10: MODS
D12: *Beta (The Forgotten Ones) | E12: Male | F12: 1
D13: SEED | E13: SEX | F13: BEAUTY | G13: HOME | J13: HEIGHT | K13: WEIGHT | L13: HAIR & EYES
D14: 6 - Immortal | E14: 5918492 | F14: 1st | G14: 1 | H14: None
D15: LIFE SPAN | E15: AGE | F15: BIRTH MONTH | G15: BIRTH DAY | H15: MONKEY PAW
J17: APPEARANCE
D22: GOALS & VALUES | J22: KARMA

Sheet SEEDDATA
A1: =IFERROR(__xludf.DUMMYFUNCTION("QUERY(IMPORTRANGE(""1LSZsvd5srg8btBs9sLMdlzhljmYMjfhdQyDyeo88BTk"",""Seeds!$B$3:$B""),""select Col1 where Col1 is not null AND NOT Col1 contains '['"",0)"),"Human") -> Human | B1: =IFERROR(__xludf.DUMMYFUNCTION("QUERY(IMPORTRANGE(""1LSZsvd5srg8btBs9sLMdlzhljmYMjfhdQyDyeo88BTk"",""Seeds!$C$3:$C""),""select Col1 where Col1 is not null AND NOT Col1 contains '['"",0)"),30.0) -> 30
A2: =IFERROR(__xludf.DUMMYFUNCTION("""COMPUTED_VALUE"""),"Altered Human") -> Altered Human | B2: =IFERROR(__xludf.DUMMYFUNCTION("""COMPUTED_VALUE"""),63.0) -> 63
A3: =IFERROR(__xludf.DUMMYFUNCTION("""COMPUTED_VALUE"""),"Neo-Human") -> Neo-Human | B3: =IFERROR(__xludf.DUMMYFUNCTION("""COMPUTED_VALUE"""),145.0) -> 145
A4: =IFERROR(__xludf.DUMMYFUNCTION("""COMPUTED_VALUE"""),"Elven") -> Elven | B4: =IFERROR(__xludf.DUMMYFUNCTION("""COMPUTED_VALUE"""),78.0) -> 78
A5: =IFERROR(__xludf.DUMMYFUNCTION("""COMPUTED_VALUE"""),"Dwarven") -> Dwarven | B5: =IFERROR(__xludf.DUMMYFUNCTION("""COMPUTED_VALUE"""),78.0) -> 78
A6: =IFERROR(__xludf.DUMMYFUNCTION("""COMPUTED_VALUE"""),"Halfling") -> Halfling | B6: =IFERROR(__xludf.DUMMYFUNCTION("""COMPUTED_VALUE"""),48.0) -> 48
A7: =IFERROR(__xludf.DUMMYFUNCTION("""COMPUTED_VALUE"""),"*Draconic") -> *Draconic | B7: =IFERROR(__xludf.DUMMYFUNCTION("""COMPUTED_VALUE"""),130.0) -> 130
A8: =IFERROR(__xludf.DUMMYFUNCTION("""COMPUTED_VALUE"""),"Tulpa") -> Tulpa | B8: =IFERROR(__xludf.DUMMYFUNCTION("""COMPUTED_VALUE"""),63.0) -> 63
A9: =IFERROR(__xludf.DUMMYFUNCTION("""COMPUTED_VALUE"""),"Homunculus") -> Homunculus | B9: =IFERROR(__xludf.DUMMYFUNCTION("""COMPUTED_VALUE"""),92.0) -> 92
A10: =IFERROR(__xludf.DUMMYFUNCTION("""COMPUTED_VALUE"""),"Cambion") -> Cambion | B10: =IFERROR(__xludf.DUMMYFUNCTION("""COMPUTED_VALUE"""),70.0) -> 70
A11: =IFERROR(__xludf.DUMMYFUNCTION("""COMPUTED_VALUE"""),"Moroi") -> Moroi | B11: =IFERROR(__xludf.DUMMYFUNCTION("""COMPUTED_VALUE"""),96.0) -> 96
A12: =IFERROR(__xludf.DUMMYFUNCTION("""COMPUTED_VALUE"""),"Nephilim") -> Nephilim | B12: =IFERROR(__xludf.DUMMYFUNCTION("""COMPUTED_VALUE"""),73.0) -> 73
A13: =IFERROR(__xludf.DUMMYFUNCTION("""COMPUTED_VALUE"""),"*Cyborg") -> *Cyborg | B13: =IFERROR(__xludf.DUMMYFUNCTION("""COMPUTED_VALUE"""),132.0) -> 132
A14: =IFERROR(__xludf.DUMMYFUNCTION("""COMPUTED_VALUE"""),"*Android") -> *Android
A15: =IFERROR(__xludf.DUMMYFUNCTION("""COMPUTED_VALUE"""),"*Tin Man") -> *Tin Man
A16: =IFERROR(__xludf.DUMMYFUNCTION("""COMPUTED_VALUE"""),"*Beta (The Forgotten Ones)") -> *Beta (The Forgotten Ones)
A17: =IFERROR(__xludf.DUMMYFUNCTION("""COMPUTED_VALUE"""),"*Turbaraptus (The Wretched)") -> *Turbaraptus (The Wretched)

Sheet Skills
C1: Basic Skills | Q1: Magic Skills
C2: SKILLS | D2: LEVEL | E2: GOVERNING ATTRIBUTES | I2: MODS | J2: SKILL CHECK | K2: EPA | L2: MAX SKILL | M2: FAILED | Q2: SKILLS | R2: LEVEL | S2: FOCUS | T2: MODS | U2: SKILL CHECK | V2: FPA | W2: MAX SKILL | X2: FAILED
C4: ATHLETICS | Q4: PILLAR OF MERCY
C5: Swim | E5: STR CON | F5: =STR -> 14 | G5: =CON -> 15 | J5: =IF(AND(D5 < 4, D5 > 1)," Coin", IF(AND(D5 < 20, D5 > 12)," d12", IF(D5 = 0, "No Skill", IF(D5 = 1, 1, " d" & 2*ROUNDDOWN(D5/2,0))))) & IF(I5>0,"+"&I5,I5) -> No Skill | K5: =MIN(F5,G5,H5) -> 14 | L5: =D5+I5 -> 0 | M5: NO | Q5: Alteration | U5: =IF(AND(R5 < 4, R5 > 1)," Coin", IF(AND(R5 < 20, R5 > 12)," d12", IF(R5 = 0, "No Skill", IF(R5 = 1, 1, " d" & 2*ROUNDDOWN(R5/2,0))))) & IF(T5>0,"+"&T5,T5) -> No Skill | V5: =IF(S5>0,S5,IF(R17="Mercy",10,IF(R17="Severity",0,5))) -> 5 | W5: =R5+W17+W18+T5 -> 0 | X5: NO
C6: Sneak | E6: DEX WIS | F6: =DEX -> 15 | G6: =WIS -> 16 | J6: =IF(AND(D6 < 4, D6 > 1)," Coin", IF(AND(D6 < 20, D6 > 12)," d12", IF(D6 = 0, "No Skill", IF(D6 = 1, 1, " d" & 2*ROUNDDOWN(D6/2,0))))) & IF(I6>0,"+"&I6,I6) -> No Skill | K6: =MIN(F6,G6,H6) -> 15 | L6: =D6+I6 -> 0 | M6: NO | Q6: Restoration | U6: =IF(AND(R6 < 4, R6 > 1)," Coin", IF(AND(R6 < 20, R6 > 12)," d12", IF(R6 = 0, "No Skill", IF(R6 = 1, 1, " d" & 2*ROUNDDOWN(R6/2,0))))) & IF(T6>0,"+"&T6,T6) -> No Skill | V6: =IF(S6>0,S6,IF(R17="Mercy",10,IF(R17="Severity",0,5))) -> 5 | W6: =R6+W17+W18+T6 -> 0 | X6: NO
C7: Manual Dexterity | E7: STR DEX | F7: =STR -> 14 | G7: =DEX -> 15 | J7: =IF(AND(D7 < 4, D7 > 1)," Coin", IF(AND(D7 < 20, D7 > 12)," d12", IF(D7 = 0, "No Skill", IF(D7 = 1, 1, " d" & 2*ROUNDDOWN(D7/2,0))))) & IF(I7>0,"+"&I7,I7) -> No Skill | K7: =MIN(F7,G7,H7) -> 14 | L7: =D7+I7 -> 0 | M7: NO | Q7: Enchantment | U7: =IF(AND(R7 < 4, R7 > 1)," Coin", IF(AND(R7 < 20, R7 > 12)," d12", IF(R7 = 0, "No Skill", IF(R7 = 1, 1, " d" & 2*ROUNDDOWN(R7/2,0))))) & IF(T7>0,"+"&T7,T7) -> No Skill | V7: =IF(S7>0,S7,IF(R17="Mercy",10,IF(R17="Severity",0,5))) -> 5 | W7: =R7+W17+W18+T7 -> 0 | X7: NO
C8: Climb | E8: STR DEX CON | F8: =STR -> 14 | G8: =DEX -> 15 | H8: =CON -> 15 | J8: =IF(AND(D8 < 4, D8 > 1)," Coin", IF(AND(D8 < 20, D8 > 12)," d12", IF(D8 = 0, "No Skill", IF(D8 = 1, 1, " d" & 2*ROUNDDOWN(D8/2,0))))) & IF(I8>0,"+"&I8,I8) -> No Skill | K8: =MIN(F8,G8,H8) -> 14 | L8: =D8+I8 -> 0 | M8: NO | Q8: PILLAR OF BALANCE
C9: Acrobatics | E9: STR DEX CHA | F9: =STR -> 14 | G9: =DEX -> 15 | H9: =CHA -> 20 | J9: =IF(AND(D9 < 4, D9 > 1)," Coin", IF(AND(D9 < 20, D9 > 12)," d12", IF(D9 = 0, "No Skill", IF(D9 = 1, 1, " d" & 2*ROUNDDOWN(D9/2,0))))) & IF(I9>0,"+"&I9,I9) -> No Skill | K9: =MIN(F9,G9,H9) -> 14 | L9: =D9+I9 -> 0 | M9: NO | Q9: Divination | U9: =IF(AND(R9 < 4, R9 > 1)," Coin", IF(AND(R9 < 20, R9 > 12)," d12", IF(R9 = 0, "No Skill", IF(R9 = 1, 1, " d" & 2*ROUNDDOWN(R9/2,0))))) & IF(T9>0,"+"&T9,T9) -> No Skill | V9: =IF(S9>0,S9,IF(R17="Mercy",5,IF(R17="Severity",5,5))) -> 5 | W9: =R9+W17+W18+T9 -> 0 | X9: NO
C10: SOCIAL SKILLS | Q10: Dissolution | U10: =IF(AND(R10 < 4, R10 > 1)," Coin", IF(AND(R10 < 20, R10 > 12)," d12", IF(R10 = 0, "No Skill", IF(R10 = 1, 1, " d" & 2*ROUNDDOWN(R10/2,0))))) & IF(T10>0,"+"&T10,T10) -> No Skill | V10: =IF(S10>0,S10,IF(R17="Mercy",5,IF(R17="Severity",5,5))) -> 5 | W10: =R10+W17+W18+T10 -> 0 | X10: NO
C11: Seduction | E11: WIS CHA | F11: =WIS -> 16 | G11: =CHA -> 20 | J11: =IF(AND(D11 < 4, D11 > 1)," Coin", IF(AND(D11 < 20, D11 > 12)," d12", IF(D11 = 0, "No Skill", IF(D11 = 1, 1, " d" & 2*ROUNDDOWN(D11/2,0))))) & IF(I11>0,"+"&I11,I11) & IF(BEAUTYMOD > 0,"+" & BEAUTYMOD, "-" & BEAUTYMOD*-1) -> No Skill-3 | K11: =MIN(F11,G11,H11) -> 16 | L11: =BEAUTYMOD+I11+D11 -> -3 | M11: NO | Q11: Abjuration | U11: =IF(AND(R11 < 4, R11 > 1)," Coin", IF(AND(R11 < 20, R11 > 12)," d12", IF(R11 = 0, "No Skill", IF(R11 = 1, 1, " d" & 2*ROUNDDOWN(R11/2,0))))) & IF(T11>0,"+"&T11,T11) -> No Skill | V11: =IF(S11>0,S11,IF(R17="Mercy",5,IF(R17="Severity",5,5))) -> 5 | W11: =R11+W17+W18+T11 -> 0 | X11: NO
C12: Intimidation | E12: STR CHA | F12: =STR -> 14 | G12: =CHA -> 20 | J12: =IF(AND(D12 < 4, D12 > 1)," Coin", IF(AND(D12 < 20, D12 > 12)," d12", IF(D12 = 0, "No Skill", IF(D12 = 1, 1, " d" & 2*ROUNDDOWN(D12/2,0))))) & IF(I12>0,"+"&I12,I12) & IF(BEAUTYMOD > 0,"-" & BEAUTYMOD, "+" & BEAUTYMOD*-1) -> No Skill+3 | K12: =MIN(F12,G12,H12) -> 14 | L12: =(BEAUTYMOD*-1)+I12+D12 -> 3 | M12: NO | Q12: Illusion | U12: =IF(AND(R12 < 4, R12 > 1)," Coin", IF(AND(R12 < 20, R12 > 12)," d12", IF(R12 = 0, "No Skill", IF(R12 = 1, 1, " d" & 2*ROUNDDOWN(R12/2,0))))) & IF(T12>0,"+"&T12,T12) -> No Skill | V12: =IF(S12>0,S12,IF(R17="Mercy",5,IF(R17="Severity",5,5))) -> 5 | W12: =R12+W17+W18+T12 -> 0 | X12: NO
C13: Negotiation | E13: INT CHA | F13: =INT -> 17 | G13: =CHA -> 20 | J13: =IF(AND(D13 < 4, D13 > 1)," Coin", IF(AND(D13 < 20, D13 > 12)," d12", IF(D13 = 0, "No Skill", IF(D13 = 1, 1, " d" & 2*ROUNDDOWN(D13/2,0))))) & IF(I13>0,"+"&I13,I13) & IF(BEAUTYMOD > 0,"+" & BEAUTYMOD, "-" & BEAUTYMOD*-1) -> No Skill-3 | K13: =MIN(F13,G13,H13) -> 17 | L13: =BEAUTYMOD+I13+D13 -> -3 | M13: NO | Q13: PILLAR OF SEVERITY
C14: Deception | E14: INT WIS | F14: =INT -> 17 | G14: =WIS -> 16 | J14: =IF(AND(D14 < 4, D14 > 1)," Coin", IF(AND(D14 < 20, D14 > 12)," d12", IF(D14 = 0, "No Skill", IF(D14 = 1, 1, " d" & 2*ROUNDDOWN(D14/2,0))))) & IF(I14>0,"+"&I14,I14) -> No Skill | K14: =MIN(F14,G14,H14) -> 16 | L14: =D14+I14 -> 0 | M14: NO | Q14: Fortune | U14: =IF(AND(R14 < 4, R14 > 1)," Coin", IF(AND(R14 < 20, R14 > 12)," d12", IF(R14 = 0, "No Skill", IF(R14 = 1, 1, " d" & 2*ROUNDDOWN(R14/2,0))))) & IF(T14>0,"+"&T14,T14) -> No Skill | V14: =IF(S14>0,S14,IF(R17="Mercy",0,IF(R17="Severity",10,5))) -> 5 | W14: =R14+W17+W18+T14 -> 0 | X14: NO
C15: Leadership | E15: INT WIS CHA | F15: =INT -> 17 | G15: =WIS -> 16 | H15: =CHA -> 20 | J15: =IF(AND(D15 < 4, D15 > 1)," Coin", IF(AND(D15 < 20, D15 > 12)," d12", IF(D15 = 0, "No Skill", IF(D15 = 1, 1, " d" & 2*ROUNDDOWN(D15/2,0))))) & IF(I15>0,"+"&I15,I15) -> No Skill | K15: =MIN(F15,G15,H15) -> 16 | L15: =D15+I15 -> 0 | M15: NO | Q15: Force | U15: =IF(AND(R15 < 4, R15 > 1)," Coin", IF(AND(R15 < 20, R15 > 12)," d12", IF(R15 = 0, "No Skill", IF(R15 = 1, 1, " d" & 2*ROUNDDOWN(R15/2,0))))) & IF(T15>0,"+"&T15,T15) -> No Skill | V15: =IF(S15>0,S15,IF(R17="Mercy",0,IF(R17="Severity",10,5))) -> 5 | W15: =R15+W17+W18+T15 -> 0 | X15: NO
C16: MARTIAL ARTS | Q16: Conjuration | U16: =IF(AND(R16 < 4, R16 > 1)," Coin", IF(AND(R16 < 20, R16 > 12)," d12", IF(R16 = 0, "No Skill", IF(R16 = 1, 1, " d" & 2*ROUNDDOWN(R16/2,0))))) & IF(T16>0,"+"&T16,T16) -> No Skill | V16: =IF(S16>0,S16,IF(R17="Mercy",0,IF(R17="Severity",10,5))) -> 5 | W16: =R16+W17+W18+T16 -> 0 | X16: NO
C17: Blades | E17: STR DEX | F17: =STR -> 14 | G17: =DEX -> 15 | J17: =IF(AND(D17 < 4, D17 > 1)," Coin", IF(AND(D17 < 20, D17 > 12)," d12", IF(D17 = 0, "No Skill", IF(D17 = 1, 1, " d" & 2*ROUNDDOWN(D17/2,0))))) & IF(I17>0,"+"&I17,I17) -> No Skill | K17: =MIN(F17,G17,H17) -> 14 | L17: =D17+I17 -> 0 | M17: NO | Q17: ATTUNEMENT | R17: None | T17: RESOURCES | U17: BODY MANA
C18: Polearms | E18: STR DEX | F18: =STR -> 14 | G18: =DEX -> 15 | J18: =IF(AND(D18 < 4, D18 > 1)," Coin", IF(AND(D18 < 20, D18 > 12)," d12", IF(D18 = 0, "No Skill", IF(D18 = 1, 1, " d" & 2*ROUNDDOWN(D18/2,0))))) & IF(I18>0,"+"&I18,I18) -> No Skill | K18: =MIN(F18,G18,H18) -> 14 | L18: =D18+I18 -> 0 | M18: NO | Q18: 0 | R18: =MAX(Main!F7,1)+Q18 -> 17 | U18: CATALYST MANA
C19: Hammers & Axes | E19: STR CON | F19: =STR -> 14 | G19: =CON -> 15 | J19: =IF(AND(D19 < 4, D19 > 1)," Coin", IF(AND(D19 < 20, D19 > 12)," d12", IF(D19 = 0, "No Skill", IF(D19 = 1, 1, " d" & 2*ROUNDDOWN(D19/2,0))))) & IF(I19>0,"+"&I19,I19) -> No Skill | K19: =MIN(F19,G19,H19) -> 14 | L19: =D19+I19 -> 0 | M19: NO
C20: Firearms | E20: DEX CHA | F20: =DEX -> 15 | G20: =CHA -> 20 | J20: =IF(AND(D20 < 4, D20 > 1)," Coin", IF(AND(D20 < 20, D20 > 12)," d12", IF(D20 = 0, "No Skill", IF(D20 = 1, 1, " d" & 2*ROUNDDOWN(D20/2,0))))) & IF(I20>0,"+"&I20,I20) -> No Skill | K20: =MIN(F20,G20,H20) -> 15 | L20: =D20+I20 -> 0 | M20: NO | Q20: LEARNING MOD | R20: LEARNING
C21: Exotic Weapons | E21: STR DEX WIS | F21: =STR -> 14 | G21: =DEX -> 15 | H21: =WIS -> 16 | J21: =IF(AND(D21 < 4, D21 > 1)," Coin", IF(AND(D21 < 20, D21 > 12)," d12", IF(D21 = 0, "No Skill", IF(D21 = 1, 1, " d" & 2*ROUNDDOWN(D21/2,0))))) & IF(I21>0,"+"&I21,I21) -> No Skill | K21: =MIN(F21,G21,H21) -> 14 | L21: =D21+I21 -> 0 | M21: NO | Q21: SKILLS TOTAL KV | R21: =FLOOR(SUM(D5:D9,D11:D15,D17:D23,D25:D27,D29:D31,D33:D36,D38:D42,D44:D48,D50:D53,D55:D57,D59:D61,D63:D65)+SUM(R5:R7,R9:R12,R14:R16)*2,1) -> 0
C22: Archery | E22: DEX CON WIS | F22: =DEX -> 15 | G22: =CON -> 15 | H22: =WIS -> 16 | J22: =IF(AND(D22 < 4, D22 > 1)," Coin", IF(AND(D22 < 20, D22 > 12)," d12", IF(D22 = 0, "No Skill", IF(D22 = 1, 1, " d" & 2*ROUNDDOWN(D22/2,0))))) & IF(I22>0,"+"&I22,I22) -> No Skill | K22: =MIN(F22,G22,H22) -> 15 | L22: =D22+I22 -> 0 | M22: NO
C23: Unarmed | E23: STR DEX CON | F23: =STR -> 14 | G23: =DEX -> 15 | H23: =CON -> 15 | J23: =IF(AND(D23 < 4, D23 > 1)," Coin", IF(AND(D23 < 20, D23 > 12)," d12", IF(D23 = 0, "No Skill", IF(D23 = 1, 1, " d" & 2*ROUNDDOWN(D23/2,0))))) & IF(I23>0,"+"&I23,I23) -> No Skill | K23: =MIN(F23,G23,H23) -> 14 | L23: =D23+I23 -> 0 | M23: NO | Q23: PASSIVE TASKS
C24: PERFORMING ARTS | R24: TYPE | T24: TIME | U24: NOTES
C25: Music | E25: INT WIS | F25: =INT -> 17 | G25: =WIS -> 16 | J25: =IF(AND(D25 < 4, D25 > 1)," Coin", IF(AND(D25 < 20, D25 > 12)," d12", IF(D25 = 0, "No Skill", IF(D25 = 1, 1, " d" & 2*ROUNDDOWN(D25/2,0))))) & IF(I25>0,"+"&I25,I25) & IF(BEAUTYMOD > 0,"+" & BEAUTYMOD, "-" & BEAUTYMOD*-1) -> No Skill-3 | K25: =MIN(F25,G25,H25) -> 16 | L25: =BEAUTYMOD+I25+D25 -> -3 | M25: NO
C26: Drama | E26: DEX WIS CHA | F26: =DEX -> 15 | G26: =WIS -> 16 | H26: =CHA -> 20 | J26: =IF(AND(D26 < 4, D26 > 1)," Coin", IF(AND(D26 < 20, D26 > 12)," d12", IF(D26 = 0, "No Skill", IF(D26 = 1, 1, " d" & 2*ROUNDDOWN(D26/2,0))))) & IF(I26>0,"+"&I26,I26) & IF(BEAUTYMOD > 0,"+" & BEAUTYMOD, "-" & BEAUTYMOD*-1) -> No Skill-3 | K26: =MIN(F26,G26,H26) -> 15 | L26: =BEAUTYMOD+I26+D26 -> -3 | M26: NO
C27: Dance | E27: STR DEX CHA | F27: =STR -> 14 | G27: =DEX -> 15 | H27: =CHA -> 20 | J27: =IF(AND(D27 < 4, D27 > 1)," Coin", IF(AND(D27 < 20, D27 > 12)," d12", IF(D27 = 0, "No Skill", IF(D27 = 1, 1, " d" & 2*ROUNDDOWN(D27/2,0))))) & IF(I27>0,"+"&I27,I27) & IF(BEAUTYMOD > 0,"+" & BEAUTYMOD, "-" & BEAUTYMOD*-1) -> No Skill-3 | K27: =MIN(F27,G27,H27) -> 14 | L27: =BEAUTYMOD+I27+D27 -> -3 | M27: NO
C28: VISUAL ARTS | Q28: STATUS EFFECTS
C29: Sculpt | E29: DEX WIS CHA | F29: =DEX -> 15 | G29: =WIS -> 16 | H29: =CHA -> 20 | J29: =IF(AND(D29 < 4, D29 > 1)," Coin", IF(AND(D29 < 20, D29 > 12)," d12", IF(D29 = 0, "No Skill", IF(D29 = 1, 1, " d" & 2*ROUNDDOWN(D29/2,0))))) & IF(I29>0,"+"&I29,I29) -> No Skill | K29: =MIN(F29,G29,H29) -> 15 | L29: =D29+I29 -> 0 | M29: NO
C30: Paint & Draw | E30: DEX WIS CHA | F30: =DEX -> 15 | G30: =WIS -> 16 | H30: =CHA -> 20 | J30: =IF(AND(D30 < 4, D30 > 1)," Coin", IF(AND(D30 < 20, D30 > 12)," d12", IF(D30 = 0, "No Skill", IF(D30 = 1, 1, " d" & 2*ROUNDDOWN(D30/2,0))))) & IF(I30>0,"+"&I30,I30) -> No Skill | K30: =MIN(F30,G30,H30) -> 15 | L30: =D30+I30 -> 0 | M30: NO
C31: Literature | E31: INT WIS CHA | F31: =INT -> 17 | G31: =WIS -> 16 | H31: =CHA -> 20 | J31: =IF(AND(D31 < 4, D31 > 1)," Coin", IF(AND(D31 < 20, D31 > 12)," d12", IF(D31 = 0, "No Skill", IF(D31 = 1, 1, " d" & 2*ROUNDDOWN(D31/2,0))))) & IF(I31>0,"+"&I31,I31) -> No Skill | K31: =MIN(F31,G31,H31) -> 16 | L31: =D31+I31 -> 0 | M31: NO
C32: SOCIAL SCIENCES
C33: History | E33: INT CHA | F33: =INT -> 17 | G33: =CHA -> 20 | J33: =IF(AND(D33 < 4, D33 > 1)," Coin", IF(AND(D33 < 20, D33 > 12)," d12", IF(D33 = 0, "No Skill", IF(D33 = 1, 1, " d" & 2*ROUNDDOWN(D33/2,0))))) & IF(I33>0,"+"&I33,I33) -> No Skill | K33: =MIN(F33,G33,H33) -> 17 | L33: =D33+I33 -> 0 | M33: NO
C34: Economics | E34: WIS CHA | F34: =WIS -> 16 | G34: =CHA -> 20 | J34: =IF(AND(D34 < 4, D34 > 1)," Coin", IF(AND(D34 < 20, D34 > 12)," d12", IF(D34 = 0, "No Skill", IF(D34 = 1, 1, " d" & 2*ROUNDDOWN(D34/2,0))))) & IF(I34>0,"+"&I34,I34) -> No Skill | K34: =MIN(F34,G34,H34) -> 16 | L34: =D34+I34 -> 0 | M34: NO
C35: Geography | E35: INT CHA | F35: =INT -> 17 | G35: =CHA -> 20 | J35: =IF(AND(D35 < 4, D35 > 1)," Coin", IF(AND(D35 < 20, D35 > 12)," d12", IF(D35 = 0, "No Skill", IF(D35 = 1, 1, " d" & 2*ROUNDDOWN(D35/2,0))))) & IF(I35>0,"+"&I35,I35) -> No Skill | K35: =MIN(F35,G35,H35) -> 17 | L35: =D35+I35 -> 0 | M35: NO
C36: Law | E36: INT WIS CHA | F36: =INT -> 17 | G36: =WIS -> 16 | H36: =CHA -> 20 | J36: =IF(AND(D36 < 4, D36 > 1)," Coin", IF(AND(D36 < 20, D36 > 12)," d12", IF(D36 = 0, "No Skill", IF(D36 = 1, 1, " d" & 2*ROUNDDOWN(D36/2,0))))) & IF(I36>0,"+"&I36,I36) -> No Skill | K36: =MIN(F36,G36,H36) -> 16 | L36: =D36+I36 -> 0 | M36: NO
C37: NATURAL SCIENCES
C38: Biology | E38: INT WIS | F38: =INT -> 17 | G38: =WIS -> 16 | J38: =IF(AND(D38 < 4, D38 > 1)," Coin", IF(AND(D38 < 20, D38 > 12)," d12", IF(D38 = 0, "No Skill", IF(D38 = 1, 1, " d" & 2*ROUNDDOWN(D38/2,0))))) & IF(I38>0,"+"&I38,I38) -> No Skill | K38: =MIN(F38,G38,H38) -> 16 | L38: =D38+I38 -> 0 | M38: NO
C39: Geoscience | E39: INT WIS | F39: =INT -> 17 | G39: =WIS -> 16 | J39: =IF(AND(D39 < 4, D39 > 1)," Coin", IF(AND(D39 < 20, D39 > 12)," d12", IF(D39 = 0, "No Skill", IF(D39 = 1, 1, " d" & 2*ROUNDDOWN(D39/2,0))))) & IF(I39>0,"+"&I39,I39) -> No Skill | K39: =MIN(F39,G39,H39) -> 16 | L39: =D39+I39 -> 0 | M39: NO
C40: Chemistry | E40: INT WIS | F40: =INT -> 17 | G40: =WIS -> 16 | J40: =IF(AND(D40 < 4, D40 > 1)," Coin", IF(AND(D40 < 20, D40 > 12)," d12", IF(D40 = 0, "No Skill", IF(D40 = 1, 1, " d" & 2*ROUNDDOWN(D40/2,0))))) & IF(I40>0,"+"&I40,I40) -> No Skill | K40: =MIN(F40,G40,H40) -> 16 | L40: =D40+I40 -> 0 | M40: NO
C41: Physics | E41: INT WIS | F41: =INT -> 17 | G41: =WIS -> 16 | J41: =IF(AND(D41 < 4, D41 > 1)," Coin", IF(AND(D41 < 20, D41 > 12)," d12", IF(D41 = 0, "No Skill", IF(D41 = 1, 1, " d" & 2*ROUNDDOWN(D41/2,0))))) & IF(I41>0,"+"&I41,I41) -> No Skill | K41: =MIN(F41,G41,H41) -> 16 | L41: =D41+I41 -> 0 | M41: NO
...

Sheet Vitals
A1: Vitals
E3: Undamaged | Q3: =IFERROR(IF(vlookup(O22,Inventory!C4:AF37,21,false)=TRUE, IF(V22="Destroyed",0,IF(V22="Broken",ROUNDUP(vlookup(O22,Inventory!C4:AF37,14,false)/2,0) & " " & vlookup(O22,Inventory!C4:AF37,15,false),vlookup(O22,Inventory!C4:AF37,14,false) & " " & vlookup(O22,Inventory!C4:AF37,15,false))), IFERROR(IF(vlookup(O23,Inventory!C4:AF37,21,false)=TRUE, IF(V23="Destroyed",0,IF(V23="Broken",ROUNDUP(vlookup(O23,Inventory!C4:AF37,14,false)/2,0) & " " & vlookup(O23,Inventory!C4:Q37,15,false),vlookup(O23,Inventory!C4:AF37,14,false) & " " & vlookup(O23,Inventory!C4:AF37,15,false))), IFERROR(IF(vlookup(O24,Inventory!C4:AF37,21,false)=TRUE, IF(V24="Destroyed",0,IF(V24="Broken",ROUNDUP(vlookup(O24,Inventory!C4:AF37,14,false)/2,0) & " " & vlookup(O24,Inventory!C4:Q37,15,false),vlookup(O24,Inventory!C4:AF37,14,false) & " " & vlookup(O24,Inventory!C4:AF37,15,false))), IFERROR(IF(vlookup(O25,Inventory!C4:AF37,21,false)=TRUE, IF(V25="Destroyed",0,IF(V25="Broken",ROUNDUP(vlookup(O25,Inventory!C4:AF37,14,false)/2,0) & " " & vlookup(O25,Inventory!C4:Q37,15,false),vlookup(O25,Inventory!C4:AF37,14,false) & " " & vlookup(O25,Inventory!C4:AF37,15,false))), IFERROR(IF(vlookup(O26,Inventory!C4:AF37,21,false)=TRUE, IF(V26="Destroyed",0,IF(V26="Broken",ROUNDUP(vlookup(O26,Inventory!C4:AF37,14,false)/2,0) & " " & vlookup(O26,Inventory!C4:Q37,15,false),vlookup(O26,Inventory!C4:AF37,14,false) & " " & vlookup(O26,Inventory!C4:AF37,15,false))), IFERROR(IF(vlookup(O27,Inventory!C4:AF37,21,false)=TRUE, IF(V27="Destroyed",0,IF(V27="Broken",ROUNDUP(vlookup(O27,Inventory!C4:AF37,14,false)/2,0) & " " & vlookup(O27,Inventory!C4:Q37,15,false),vlookup(O27,Inventory!C4:AF37,14,false) & " " & vlookup(O27,Inventory!C4:AF37,15,false))), IFERROR(IF(vlookup(O28,Inventory!C4:AF37,21,false)=TRUE, IF(V28="Destroyed",0,IF(V28="Broken",ROUNDUP(vlookup(O28,Inventory!C4:AF37,14,false)/2,0) & " " & vlookup(O28,Inventory!C4:Q37,15,false),vlookup(O28,Inventory!C4:AF37,14,false) & " " & vlookup(O28,Inventory!C4:AF37,15,false))), IFERROR(IF(vlookup(O29,Inventory!C4:AF37,21,false)=TRUE, IF(V29="Destroyed",0,IF(V29="Broken",ROUNDUP(vlookup(O29,Inventory!C4:AF37,14,false)/2,0) & " " & vlookup(O29,Inventory!C4:Q37,15,false),vlookup(O29,Inventory!C4:AF37,14,false) & " " & vlookup(O29,Inventory!C4:AF37,15,false))), IFERROR(IF(vlookup(O30,Inventory!C4:AF37,21,false)=TRUE, IF(V30="Destroyed",0,IF(V30="Broken",ROUNDUP(vlookup(O30,Inventory!C4:AF37,14,false)/2,0) & " " & vlookup(O30,Inventory!C4:Q37,15,false),vlookup(O30,Inventory!C4:AF37,14,false) & " " & vlookup(O30,Inventory!C4:Q37,15,false))), IFERROR(IF(vlookup(O31,Inventory!C4:AF37,21,false)=TRUE, IF(V31="Destroyed",0,IF(V31="Broken",ROUNDUP(vlookup(O31,Inventory!C4:AF37,14,false)/2,0) & " " & vlookup(O31,Inventory!C4:Q37,15,false),vlookup(O31,Inventory!C4:AF37,14,false) & " " & vlookup(O31,Inventory!C4:Q37,15,false)))),"")),"")),"")),"")),"") ),"")),"")),"")),"")),"") | AK3: =IFERROR(IF(vlookup(AI22,Inventory!C4:AF37,21,false)=TRUE, IF(AP22="Destroyed",0,IF(AP22="Broken",ROUNDUP(vlookup(AI22,Inventory!C4:AF37,14,false)/2,0) & " " & vlookup(AI22,Inventory!C4:AF37,15,false),vlookup(AI22,Inventory!C4:AF37,14,false) & " " & vlookup(AI22,Inventory!C4:AF37,15,false))), IFERROR(IF(vlookup(AI23,Inventory!C4:AF37,21,false)=TRUE, IF(AP23="Destroyed",0,IF(AP23="Broken",ROUNDUP(vlookup(AI23,Inventory!C4:AF37,14,false)/2,0) & " " & vlookup(AI23,Inventory!C4:Q37,15,false),vlookup(AI23,Inventory!C4:AF37,14,false) & " " & vlookup(AI23,Inventory!C4:AF37,15,false))), IFERROR(IF(vlookup(AI24,Inventory!C4:AF37,21,false)=TRUE, IF(AP24="Destroyed",0,IF(AP24="Broken",ROUNDUP(vlookup(AI24,Inventory!C4:AF37,14,false)/2,0) & " " & vlookup(AI24,Inventory!C4:Q37,15,false),vlookup(AI24,Inventory!C4:AF37,14,false) & " " & vlookup(AI24,Inventory!C4:AF37,15,false))), IFERROR(IF(vlookup(AI25,Inventory!C4:AF37,21,false)=TRUE, IF(AP25="Destroyed",0,IF(AP25="Broken",ROUNDUP(vlookup(AI25,Inventory!C4:AF37,14,false)/2,0) & " " & vlookup(AI25,Inventory!C4:Q37,15,false),vlookup(AI25,Inventory!C4:AF37,14,false) & " " & vlookup(AI25,Inventory!C4:AF37,15,false))), IFERROR(IF(vlookup(AI26,Inventory!C4:AF37,21,false)=TRUE, IF(AP26="Destroyed",0,IF(AP26="Broken",ROUNDUP(vlookup(AI26,Inventory!C4:AF37,14,false)/2,0) & " " & vlookup(AI26,Inventory!C4:Q37,15,false),vlookup(AI26,Inventory!C4:AF37,14,false) & " " & vlookup(AI26,Inventory!C4:AF37,15,false))), IFERROR(IF(vlookup(AI27,Inventory!C4:AF37,21,false)=TRUE, IF(AP27="Destroyed",0,IF(AP27="Broken",ROUNDUP(vlookup(AI27,Inventory!C4:AF37,14,false)/2,0) & " " & vlookup(AI27,Inventory!C4:Q37,15,false),vlookup(AI27,Inventory!C4:AF37,14,false) & " " & vlookup(AI27,Inventory!C4:AF37,15,false))), IFERROR(IF(vlookup(AI28,Inventory!C4:AF37,21,false)=TRUE, IF(AP28="Destroyed",0,IF(AP28="Broken",ROUNDUP(vlookup(AI28,Inventory!C4:AF37,14,false)/2,0) & " " & vlookup(AI28,Inventory!C4:Q37,15,false),vlookup(AI28,Inventory!C4:AF37,14,false) & " " & vlookup(AI28,Inventory!C4:AF37,15,false))), IFERROR(IF(vlookup(AI29,Inventory!C4:AF37,21,false)=TRUE, IF(AP29="Destroyed",0,IF(AP29="Broken",ROUNDUP(vlookup(AI29,Inventory!C4:AF37,14,false)/2,0) & " " & vlookup(AI29,Inventory!C4:Q37,15,false),vlookup(AI29,Inventory!C4:AF37,14,false) & " " & vlookup(AI29,Inventory!C4:AF37,15,false))), IFERROR(IF(vlookup(AI30,Inventory!C4:AF37,21,false)=TRUE, IF(AP30="Destroyed",0,IF(AP30="Broken",ROUNDUP(vlookup(AI30,Inventory!C4:AF37,14,false)/2,0) & " " & vlookup(AI30,Inventory!C4:Q37,15,false),vlookup(AI30,Inventory!C4:AF37,14,false) & " " & vlookup(AI30,Inventory!C4:Q37,15,false))), IFERROR(IF(vlookup(AI31,Inventory!C4:AF37,21,false)=TRUE, IF(AP31="Destroyed",0,IF(AP31="Broken",ROUNDUP(vlookup(AI31,Inventory!C4:AF37,14,false)/2,0) & " " & vlookup(AI31,Inventory!C4:Q37,15,false),vlookup(AI31,Inventory!C4:AF37,14,false) & " " & vlookup(AI31,Inventory!C4:Q37,15,false)))),"")),"")),"")),"")),"") ),"")),"")),"")),"")),"") | BE3: =IFERROR(IF(vlookup(BC22,Inventory!C4:AF37,21,false)=TRUE, IF(BJ22="Destroyed",0,IF(BJ22="Broken",ROUNDUP(vlookup(BC22,Inventory!C4:AF37,14,false)/2,0) & " " & vlookup(BC22,Inventory!C4:AF37,15,false),vlookup(BC22,Inventory!C4:AF37,14,false) & " " & vlookup(BC22,Inventory!C4:AF37,15,false))), IFERROR(IF(vlookup(BC23,Inventory!C4:AF37,21,false)=TRUE, IF(BJ23="Destroyed",0,IF(BJ23="Broken",ROUNDUP(vlookup(BC23,Inventory!C4:AF37,14,false)/2,0) & " " & vlookup(BC23,Inventory!C4:Q37,15,false),vlookup(BC23,Inventory!C4:AF37,14,false) & " " & vlookup(BC23,Inventory!C4:AF37,15,false))), IFERROR(IF(vlookup(BC24,Inventory!C4:AF37,21,false)=TRUE, IF(BJ24="Destroyed",0,IF(BJ24="Broken",ROUNDUP(vlookup(BC24,Inventory!C4:AF37,14,false)/2,0) & " " & vlookup(BC24,Inventory!C4:Q37,15,false),vlookup(BC24,Inventory!C4:AF37,14,false) & " " & vlookup(BC24,Inventory!C4:AF37,15,false))), IFERROR(IF(vlookup(BC25,Inventory!C4:AF37,21,false)=TRUE, IF(BJ25="Destroyed",0,IF(BJ25="Broken",ROUNDUP(vlookup(BC25,Inventory!C4:AF37,14,false)/2,0) & " " & vlookup(BC25,Inventory!C4:Q37,15,false),vlookup(BC25,Inventory!C4:AF37,14,false) & " " & vlookup(BC25,Inventory!C4:AF37,15,false))), IFERROR(IF(vlookup(BC26,Inventory!C4:AF37,21,false)=TRUE, IF(BJ26="Destroyed",0,IF(BJ26="Broken",ROUNDUP(vlookup(BC26,Inventory!C4:AF37,14,false)/2,0) & " " & vlookup(BC26,Inventory!C4:Q37,15,false),vlookup(BC26,Inventory!C4:AF37,14,false) & " " & vlookup(BC26,Inventory!C4:AF37,15,false))), IFERROR(IF(vlookup(BC27,Inventory!C4:AF37,21,false)=TRUE, IF(BJ27="Destroyed",0,IF(BJ27="Broken",ROUNDUP(vlookup(BC27,Inventory!C4:AF37,14,false)/2,0) & " " & vlookup(BC27,Inventory!C4:Q37,15,false),vlookup(BC27,Inventory!C4:AF37,14,false) & " " & vlookup(BC27,Inventory!C4:AF37,15,false))), IFERROR(IF(vlookup(BC28,Inventory!C4:AF37,21,false)=TRUE, IF(BJ28="Destroyed",0,IF(BJ28="Broken",ROUNDUP(vlookup(BC28,Inventory!C4:AF37,14,false)/2,0) & " " & vlookup(BC28,Inventory!C4:Q37,15,false),vlookup(BC28,Inventory!C4:AF37,14,false) & " " & vlookup(BC28,Inventory!C4:AF37,15,false))), IFERROR(IF(vlookup(BC29,Inventory!C4:AF37,21,false)=TRUE, IF(BJ29="Destroyed",0,IF(BJ29="Broken",ROUNDUP(vlookup(BC29,Inventory!C4:AF37,14,false)/2,0) & " " & vlookup(BC29,Inventory!C4:Q37,15,false),vlookup(BC29,Inventory!C4:AF37,14,false) & " " & vlookup(BC29,Inventory!C4:AF37,15,false))), IFERROR(IF(vlookup(BC30,Inventory!C4:AF37,21,false)=TRUE, IF(BJ30="Destroyed",0,IF(BJ30="Broken",ROUNDUP(vlookup(BC30,Inventory!C4:AF37,14,false)/2,0) & " " & vlookup(BC30,Inventory!C4:Q37,15,false),vlookup(BC30,Inventory!C4:AF37,14,false) & " " & vlookup(BC30,Inventory!C4:Q37,15,false))), IFERROR(IF(vlookup(BC31,Inventory!C4:AF37,21,false)=TRUE, IF(BJ31="Destroyed",0,IF(BJ31="Broken",ROUNDUP(vlookup(BC31,Inventory!C4:AF37,14,false)/2,0) & " " & vlookup(BC31,Inventory!C4:Q37,15,false),vlookup(BC31,Inventory!C4:AF37,14,false) & " " & vlookup(BC31,Inventory!C4:Q37,15,false)))),"")),"")),"")),"")),"") ),"")),"")),"")),"")),"")
E5: =IF(E3="Broken", ROUNDDOWN(MAX((TOUGHNESS/2+RESISTMOD)/2, 1),0),ROUNDDOWN(MAX(TOUGHNESS/2+RESISTMOD, 1),0)) -> 27 | Q5: =IFERROR(IF(vlookup(O22,Inventory!C4:AF37,21,false)=TRUE,IF(vlookup(O22,Inventory!C4:AF37,16,false)="R","F","")& IF(vlookup(O22,Inventory!C4:AF37,17,false)="R","C","")& IF(vlookup(O22,Inventory!C4:AF37,18,false)="R","E","")& IF(vlookup(O22,Inventory!C4:AF37,19,false)="R","A","")& " Resist", IFERROR(IF(vlookup(O23,Inventory!C4:AF37,21,false)=TRUE,IF(vlookup(O23,Inventory!C4:AF37,16,false)="R","F","")& IF(vlookup(O23,Inventory!C4:AF37,17,false)="R","C","")& IF(vlookup(O23,Inventory!C4:AF37,18,false)="R","E","")& IF(vlookup(O23,Inventory!C4:AF37,19,false)="R","A","")& " Resist", IFERROR(IF(vlookup(O24,Inventory!C4:AF37,21,false)=TRUE,IF(vlookup(O24,Inventory!C4:AF37,16,false)="R","F","")& IF(vlookup(O24,Inventory!C4:AF37,17,false)="R","C","")& IF(vlookup(O24,Inventory!C4:AF37,18,false)="R","E","")& IF(vlookup(O24,Inventory!C4:AF37,19,false)="R","A","")& " Resist", IFERROR(IF(vlookup(O25,Inventory!C4:AF37,21,false)=TRUE,IF(vlookup(O25,Inventory!C4:AF37,16,false)="R","F","")& IF(vlookup(O25,Inventory!C4:AF37,17,false)="R","C","")& IF(vlookup(O25,Inventory!C4:AF37,18,false)="R","E","")& IF(vlookup(O25,Inventory!C4:AF37,19,false)="R","A","")& " Resist", IFERROR(IF(vlookup(O26,Inventory!C4:AF37,21,false)=TRUE,IF(vlookup(O26,Inventory!C4:AF37,16,false)="R","F","")& IF(vlookup(O26,Inventory!C4:AF37,17,false)="R","C","")& IF(vlookup(O26,Inventory!C4:AF37,18,false)="R","E","")& IF(vlookup(O26,Inventory!C4:AF37,19,false)="R","A","")& " Resist", IFERROR(IF(vlookup(O27,Inventory!C4:AF37,21,false)=TRUE,IF(vlookup(O27,Inventory!C4:AF37,16,false)="R","F","")& IF(vlookup(O27,Inventory!C4:AF37,17,false)="R","C","")& IF(vlookup(O27,Inventory!C4:AF37,18,false)="R","E","")& IF(vlookup(O27,Inventory!C4:AF37,19,false)="R","A","")& " Resist", IFERROR(IF(vlookup(O28,Inventory!C4:AF37,21,false)=TRUE,IF(vlookup(O28,Inventory!C4:AF37,16,false)="R","F","")& IF(vlookup(O28,Inventory!C4:AF37,17,false)="R","C","")& IF(vlookup(O28,Inventory!C4:AF37,18,false)="R","E","")& IF(vlookup(O28,Inventory!C4:AF37,19,false)="R","A","")& " Resist", IFERROR(IF(vlookup(O29,Inventory!C4:AF37,21,false)=TRUE,IF(vlookup(O29,Inventory!C4:AF37,16,false)="R","F","")& IF(vlookup(O29,Inventory!C4:AF37,17,false)="R","C","")& IF(vlookup(O29,Inventory!C4:AF37,18,false)="R","E","")& IF(vlookup(O29,Inventory!C4:AF37,19,false)="R","A","")& " Resist", IFERROR(IF(vlookup(O30,Inventory!C4:AF37,21,false)=TRUE,IF(vlookup(O30,Inventory!C4:AF37,16,false)="R","F","")& IF(vlookup(O30,Inventory!C4:AF37,17,false)="R","C","")& IF(vlookup(O30,Inventory!C4:AF37,18,false)="R","E","")& IF(vlookup(O30,Inventory!C4:AF37,19,false)="R","A","")& " Resist", IFERROR(IF(vlookup(O31,Inventory!C4:AF37,21,false)=TRUE,IF(vlookup(O31,Inventory!C4:AF37,16,false)="R","F","")& IF(vlookup(O31,Inventory!C4:AF37,17,false)="R","C","")& IF(vlookup(O31,Inventory!C4:AF37,18,false)="R","E","")& IF(vlookup(O31,Inventory!C4:AF37,19,false)="R","A","")& " Resist"),"")),"")),"")),"")),"")),"")),"")),"")),"")),"") | V5: =IFERROR(IF(vlookup(O22,Inventory!C4:AF37,21,false)=TRUE,IF(vlookup(O22,Inventory!C4:AF37,16,false)="P","F","")& IF(vlookup(O22,Inventory!C4:AF37,17,false)="P","C","")& IF(vlookup(O22,Inventory!C4:AF37,18,false)="P","E","")& IF(vlookup(O22,Inventory!C4:AF37,19,false)="P","A","")& " Proof", IFERROR(IF(vlookup(O23,Inventory!C4:AF37,21,false)=TRUE,IF(vlookup(O23,Inventory!C4:AF37,16,false)="P","F","")& IF(vlookup(O23,Inventory!C4:AF37,17,false)="P","C","")& IF(vlookup(O23,Inventory!C4:AF37,18,false)="P","E","")& IF(vlookup(O23,Inventory!C4:AF37,19,false)="P","A","")& " Proof", IFERROR(IF(vlookup(O24,Inventory!C4:AF37,21,false)=TRUE,IF(vlookup(O24,Inventory!C4:AF37,16,false)="P","F","")& IF(vlookup(O24,Inventory!C4:AF37,17,false)="P","C","")& IF(vlookup(O24,Inventory!C4:AF37,18,false)="P","E","")& IF(vlookup(O24,Inventory!C4:AF37,19,false)="P","A","")& " Resist", IFERROR(IF(vlookup(O25,Inventory!C4:AF37,21,false)=TRUE,IF(vlookup(O25,Inventory!C4:AF37,16,false)="P","F","")& IF(vlookup(O25,Inventory!C4:AF37,17,false)="P","C","")& IF(vlookup(O25,Inventory!C4:AF37,18,false)="P","E","")& IF(vlookup(O25,Inventory!C4:AF37,19,false)="P","A","")& " Proof", IFERROR(IF(vlookup(O26,Inventory!C4:AF37,21,false)=TRUE,IF(vlookup(O26,Inventory!C4:AF37,16,false)="P","F","")& IF(vlookup(O26,Inventory!C4:AF37,17,false)="P","C","")& IF(vlookup(O26,Inventory!C4:AF37,18,false)="P","E","")& IF(vlookup(O26,Inventory!C4:AF37,19,false)="P","A","")& " Proof", IFERROR(IF(vlookup(O27,Inventory!C4:AF37,21,false)=TRUE,IF(vlookup(O27,Inventory!C4:AF37,16,false)="P","F","")& IF(vlookup(O27,Inventory!C4:AF37,17,false)="P","C","")& IF(vlookup(O27,Inventory!C4:AF37,18,false)="P","E","")& IF(vlookup(O27,Inventory!C4:AF37,19,false)="P","A","")& " Proof", IFERROR(IF(vlookup(O28,Inventory!C4:AF37,21,false)=TRUE,IF(vlookup(O28,Inventory!C4:AF37,16,false)="P","F","")& IF(vlookup(O28,Inventory!C4:AF37,17,false)="P","C","")& IF(vlookup(O28,Inventory!C4:AF37,18,false)="P","E","")& IF(vlookup(O28,Inventory!C4:AF37,19,false)="P","A","")& " Proof", IFERROR(IF(vlookup(O29,Inventory!C4:AF37,21,false)=TRUE,IF(vlookup(O29,Inventory!C4:AF37,16,false)="P","F","")& IF(vlookup(O29,Inventory!C4:AF37,17,false)="P","C","")& IF(vlookup(O29,Inventory!C4:AF37,18,false)="P","E","")& IF(vlookup(O29,Inventory!C4:AF37,19,false)="P","A","")& " Proof", IFERROR(IF(vlookup(O30,Inventory!C4:AF37,21,false)=TRUE,IF(vlookup(O30,Inventory!C4:AF37,16,false)="P","F","")& IF(vlookup(O30,Inventory!C4:AF37,17,false)="P","C","")& IF(vlookup(O30,Inventory!C4:AF37,18,false)="P","E","")& IF(vlookup(O30,Inventory!C4:AF37,19,false)="P","A","")& " Proof", IFERROR(IF(vlookup(O31,Inventory!C4:AF37,21,false)=TRUE,IF(vlookup(O31,Inventory!C4:AF37,16,false)="P","F","")& IF(vlookup(O31,Inventory!C4:AF37,17,false)="P","C","")& IF(vlookup(O31,Inventory!C4:AF37,18,false)="P","E","")& IF(vlookup(O31,Inventory!C4:AF37,19,false)="P","A","")& " Proof"),"")),"")),"")),"")),"")),"")),"")),"")),"")),"") | AK5: =IFERROR(IF(vlookup(AI22,Inventory!C4:AF37,21,false)=TRUE,IF(vlookup(AI22,Inventory!C4:AF37,16,false)="R","F","")& IF(vlookup(AI22,Inventory!C4:AF37,17,false)="R","C","")& IF(vlookup(AI22,Inventory!C4:AF37,18,false)="R","E","")& IF(vlookup(AI22,Inventory!C4:AF37,19,false)="R","A","")& " Resist", IFERROR(IF(vlookup(AI23,Inventory!C4:AF37,21,false)=TRUE,IF(vlookup(AI23,Inventory!C4:AF37,16,false)="R","F","")& IF(vlookup(AI23,Inventory!C4:AF37,17,false)="R","C","")& IF(vlookup(AI23,Inventory!C4:AF37,18,false)="R","E","")& IF(vlookup(AI23,Inventory!C4:AF37,19,false)="R","A","")& " Resist", IFERROR(IF(vlookup(AI24,Inventory!C4:AF37,21,false)=TRUE,IF(vlookup(AI24,Inventory!C4:AF37,16,false)="R","F","")& IF(vlookup(AI24,Inventory!C4:AF37,17,false)="R","C","")& IF(vlookup(AI24,Inventory!C4:AF37,18,false)="R","E","")& IF(vlookup(AI24,Inventory!C4:AF37,19,false)="R","A","")& " Resist", IFERROR(IF(vlookup(AI25,Inventory!C4:AF37,21,false)=TRUE,IF(vlookup(AI25,Inventory!C4:AF37,16,false)="R","F","")& IF(vlookup(AI25,Inventory!C4:AF37,17,false)="R","C","")& IF(vlookup(AI25,Inventory!C4:AF37,18,false)="R","E","")& IF(vlookup(AI25,Inventory!C4:AF37,19,false)="R","A","")& " Resist", IFERROR(IF(vlookup(AI26,Inventory!C4:AF37,21,false)=TRUE,IF(vlookup(AI26,Inventory!C4:AF37,16,false)="R","F","")& IF(vlookup(AI26,Inventory!C4:AF37,17,false)="R","C","")& IF(vlookup(AI26,Inventory!C4:AF37,18,false)="R","E","")& IF(vlookup(AI26,Inventory!C4:AF37,19,false)="R","A","")& " Resist", IFERROR(IF(vlookup(AI27,Inventory!C4:AF37,21,false)=TRUE,IF(vlookup(AI27,Inventory!C4:AF37,16,false)="R","F","")& IF(vlookup(AI27,Inventory!C4:AF37,17,false)="R","C","")& IF(vlookup(AI27,Inventory!C4:AF37,18,false)="R","E","")& IF(vlookup(AI27,Inventory!C4:AF37,19,false)="R","A","")& " Resist", IFERROR(IF(vlookup(AI28,Inventory!C4:AF37,21,false)=TRUE,IF(vlookup(AI28,Inventory!C4:AF37,16,false)="R","F","")& IF(vlookup(AI28,Inventory!C4:AF37,17,false)="R","C","")& IF(vlookup(AI28,Inventory!C4:AF37,18,false)="R","E","")& IF(vlookup(AI28,Inventory!C4:AF37,19,false)="R","A","")& " Resist", IFERROR(IF(vlookup(AI29,Inventory!C4:AF37,21,false)=TRUE,IF(vlookup(AI29,Inventory!C4:AF37,16,false)="R","F","")& IF(vlookup(AI29,Inventory!C4:AF37,17,false)="R","C","")& IF(vlookup(AI29,Inventory!C4:AF37,18,false)="R","E","")& IF(vlookup(AI29,Inventory!C4:AF37,19,false)="R","A","")& " Resist", IFERROR(IF(vlookup(AI30,Inventory!C4:AF37,21,false)=TRUE,IF(vlookup(AI30,Inventory!C4:AF37,16,false)="R","F","")& IF(vlookup(AI30,Inventory!C4:AF37,17,false)="R","C","")& IF(vlookup(AI30,Inventory!C4:AF37,18,false)="R","E","")& IF(vlookup(AI30,Inventory!C4:AF37,19,false)="R","A","")& " Resist", IFERROR(IF(vlookup(AI31,Inventory!C4:AF37,21,false)=TRUE,IF(vlookup(AI31,Inventory!C4:AF37,16,false)="R","F","")& IF(vlookup(AI31,Inventory!C4:AF37,17,false)="R","C","")& IF(vlookup(AI31,Inventory!C4:AF37,18,false)="R","E","")& IF(vlookup(AI31,Inventory!C4:AF37,19,false)="R","A","")& " Resist"),""),),"")),"")),"")),"")),"")),"")),"")),"")),"") | AP5: =IFERROR(IF(vlookup(AI22,Inventory!C4:AF37,21,false)=TRUE,IF(vlookup(AI22,Inventory!C4:AF37,16,false)="P","F","")& IF(vlookup(AI22,Inventory!C4:AF37,17,false)="P","C","")& IF(vlookup(AI22,Inventory!C4:AF37,18,false)="P","E","")& IF(vlookup(AI22,Inventory!C4:AF37,19,false)="P","A","")& " Proof", IFERROR(IF(vlookup(AI23,Inventory!C4:AF37,21,false)=TRUE,IF(vlookup(AI23,Inventory!C4:AF37,16,false)="P","F","")& IF(vlookup(AI23,Inventory!C4:AF37,17,false)="P","C","")& IF(vlookup(AI23,Inventory!C4:AF37,18,false)="P","E","")& IF(vlookup(AI23,Inventory!C4:AF37,19,false)="P","A","")& " Proof", IFERROR(IF(vlookup(AI24,Inventory!C4:AF37,21,false)=TRUE,IF(vlookup(AI24,Inventory!C4:AF37,16,false)="P","F","")& IF(vlookup(AI24,Inventory!C4:AF37,17,false)="P","C","")& IF(vlookup(AI24,Inventory!C4:AF37,18,false)="P","E","")& IF(vlookup(AI24,Inventory!C4:AF37,19,false)="P","A","")& " Proof", IFERROR(IF(vlookup(AI25,Inventory!C4:AF37,21,false)=TRUE,IF(vlookup(AI25,Inventory!C4:AF37,16,false)="P","F","")& IF(vlookup(AI25,Inventory!C4:AF37,17,false)="P","C","")& IF(vlookup(AI25,Inventory!C4:AF37,18,false)="P","E","")& IF(vlookup(AI25,Inventory!C4:AF37,19,false)="P","A","")& " Proof", IFERROR(IF(vlookup(AI26,Inventory!C4:AF37,21,false)=TRUE,IF(vlookup(AI26,Inventory!C4:AF37,16,false)="P","F","")& IF(vlookup(AI26,Inventory!C4:AF37,17,false)="P","C","")& IF(vlookup(AI26,Inventory!C4:AF37,18,false)="P","E","")& IF(vlookup(AI26,Inventory!C4:AF37,19,false)="P","A","")& " Proof", IFERROR(IF(vlookup(AI27,Inventory!C4:AF37,21,false)=TRUE,IF(vlookup(AI27,Inventory!C4:AF37,16,false)="P","F","")& IF(vlookup(AI27,Inventory!C4:AF37,17,false)="P","C","")& IF(vlookup(AI27,Inventory!C4:AF37,18,false)="P","E","")& IF(vlookup(AI27,Inventory!C4:AF37,19,false)="P","A","")& " Proof", IFERROR(IF(vlookup(AI28,Inventory!C4:AF37,21,false)=TRUE,IF(vlookup(AI28,Inventory!C4:AF37,16,false)="P","F","")& IF(vlookup(AI28,Inventory!C4:AF37,17,false)="P","C","")& IF(vlookup(AI28,Inventory!C4:AF37,18,false)="P","E","")& IF(vlookup(AI28,Inventory!C4:AF37,19,false)="P","A","")& " Proof", IFERROR(IF(vlookup(AI29,Inventory!C4:AF37,21,false)=TRUE,IF(vlookup(AI29,Inventory!C4:AF37,16,false)="P","F","")& IF(vlookup(AI29,Inventory!C4:AF37,17,false)="P","C","")& IF(vlookup(AI29,Inventory!C4:AF37,18,false)="P","E","")& IF(vlookup(AI29,Inventory!C4:AF37,19,false)="P","A","")& " Proof", IFERROR(IF(vlookup(AI30,Inventory!C4:AF37,21,false)=TRUE,IF(vlookup(AI30,Inventory!C4:AF37,16,false)="P","F","")& IF(vlookup(AI30,Inventory!C4:AF37,17,false)="P","C","")& IF(vlookup(AI30,Inventory!C4:AF37,18,false)="P","E","")& IF(vlookup(AI30,Inventory!C4:AF37,19,false)="P","A","")& " Proof", IFERROR(IF(vlookup(AI31,Inventory!C4:AF37,21,false)=TRUE,IF(vlookup(AI31,Inventory!C4:AF37,16,false)="P","F","")& IF(vlookup(AI31,Inventory!C4:AF37,17,false)="P","C","")& IF(vlookup(AI31,Inventory!C4:AF37,18,false)="P","E","")& IF(vlookup(AI31,Inventory!C4:AF37,19,false)="P","A","")& " Proof"),""),),"")),"")),"")),"")),"")),"")),"")),"")),"") | BE5: =IFERROR(IF(vlookup(BC22,Inventory!C4:AF37,21,false)=TRUE,IF(vlookup(BC22,Inventory!C4:AF37,16,false)="R","F","")& IF(vlookup(BC22,Inventory!C4:AF37,17,false)="R","C","")& IF(vlookup(BC22,Inventory!C4:AF37,18,false)="R","E","")& IF(vlookup(BC22,Inventory!C4:AF37,19,false)="R","A","")& " Resist", IFERROR(IF(vlookup(BC23,Inventory!C4:AF37,21,false)=TRUE,IF(vlookup(BC23,Inventory!C4:AF37,16,false)="R","F","")& IF(vlookup(BC23,Inventory!C4:AF37,17,false)="R","C","")& IF(vlookup(BC23,Inventory!C4:AF37,18,false)="R","E","")& IF(vlookup(BC23,Inventory!C4:AF37,19,false)="R","A","")& " Resist", IFERROR(IF(vlookup(BC24,Inventory!C4:AF37,21,false)=TRUE,IF(vlookup(BC24,Inventory!C4:AF37,16,false)="R","F","")& IF(vlookup(BC24,Inventory!C4:AF37,17,false)="R","C","")& IF(vlookup(BC24,Inventory!C4:AF37,18,false)="R","E","")& IF(vlookup(BC24,Inventory!C4:AF37,19,false)="R","A","")& " Resist", IFERROR(IF(vlookup(BC25,Inventory!C4:AF37,21,false)=TRUE,IF(vlookup(BC25,Inventory!C4:AF37,16,false)="R","F","")& IF(vlookup(BC25,Inventory!C4:AF37,17,false)="R","C","")& IF(vlookup(BC25,Inventory!C4:AF37,18,false)="R","E","")& IF(vlookup(BC25,Inventory!C4:AF37,19,false)="R","A","")& " Resist", IFERROR(IF(vlookup(BC26,Inventory!C4:AF37,21,false)=TRUE,IF(vlookup(BC26,Inventory!C4:AF37,16,false)="R","F","")& IF(vlookup(BC26,Inventory!C4:AF37,17,false)="R","C","")& IF(vlookup(BC26,Inventory!C4:AF37,18,false)="R","E","")& IF(vlookup(BC26,Inventory!C4:AF37,19,false)="R","A","")& " Resist", IFERROR(IF(vlookup(BC27,Inventory!C4:AF37,21,false)=TRUE,IF(vlookup(BC27,Inventory!C4:AF37,16,false)="R","F","")& IF(vlookup(BC27,Inventory!C4:AF37,17,false)="R","C","")& IF(vlookup(BC27,Inventory!C4:AF37,18,false)="R","E","")& IF(vlookup(BC27,Inventory!C4:AF37,19,false)="R","A","")& " Resist", IFERROR(IF(vlookup(BC28,Inventory!C4:AF37,21,false)=TRUE,IF(vlookup(BC28,Inventory!C4:AF37,16,false)="R","F","")& IF(vlookup(BC28,Inventory!C4:AF37,17,false)="R","C","")& IF(vlookup(BC28,Inventory!C4:AF37,18,false)="R","E","")& IF(vlookup(BC28,Inventory!C4:AF37,19,false)="R","A","")& " Resist", IFERROR(IF(vlookup(BC29,Inventory!C4:AF37,21,false)=TRUE,IF(vlookup(BC29,Inventory!C4:AF37,16,false)="R","F","")& IF(vlookup(BC29,Inventory!C4:AF37,17,false)="R","C","")& IF(vlookup(BC29,Inventory!C4:AF37,18,false)="R","E","")& IF(vlookup(BC29,Inventory!C4:AF37,19,false)="R","A","")& " Resist", IFERROR(IF(vlookup(BC30,Inventory!C4:AF37,21,false)=TRUE,IF(vlookup(BC30,Inventory!C4:AF37,16,false)="R","F","")& IF(vlookup(BC30,Inventory!C4:AF37,17,false)="R","C","")& IF(vlookup(BC30,Inventory!C4:AF37,18,false)="R","E","")& IF(vlookup(BC30,Inventory!C4:AF37,19,false)="R","A","")& " Resist", IFERROR(IF(vlookup(BC31,Inventory!C4:AF37,21,false)=TRUE,IF(vlookup(BC31,Inventory!C4:AF37,16,false)="R","F","")& IF(vlookup(BC31,Inventory!C4:AF37,17,false)="R","C","")& IF(vlookup(BC31,Inventory!C4:AF37,18,false)="R","E","")& IF(vlookup(BC31,Inventory!C4:AF37,19,false)="R","A","")& " Resist"),""),),"")),"")),"")),"")),"")),"")),"")),"")),"") | BJ5: =IFERROR(IF(vlookup(BC22,Inventory!C4:AF37,21,false)=TRUE,IF(vlookup(BC22,Inventory!C4:AF37,16,false)="P","F","")& IF(vlookup(BC22,Inventory!C4:AF37,17,false)="P","C","")& IF(vlookup(BC22,Inventory!C4:AF37,18,false)="P","E","")& IF(vlookup(BC22,Inventory!C4:AF37,19,false)="P","A","")& " Proof", IFERROR(IF(vlookup(BC23,Inventory!C4:AF37,21,false)=TRUE,IF(vlookup(BC23,Inventory!C4:AF37,16,false)="P","F","")& IF(vlookup(BC23,Inventory!C4:AF37,17,false)="P","C","")& IF(vlookup(BC23,Inventory!C4:AF37,18,false)="P","E","")& IF(vlookup(BC23,Inventory!C4:AF37,19,false)="P","A","")& " Proof", IFERROR(IF(vlookup(BC24,Inventory!C4:AF37,21,false)=TRUE,IF(vlookup(BC24,Inventory!C4:AF37,16,false)="P","F","")& IF(vlookup(BC24,Inventory!C4:AF37,17,false)="P","C","")& IF(vlookup(BC24,Inventory!C4:AF37,18,false)="P","E","")& IF(vlookup(BC24,Inventory!C4:AF37,19,false)="P","A","")& " Proof", IFERROR(IF(vlookup(BC25,Inventory!C4:AF37,21,false)=TRUE,IF(vlookup(BC25,Inventory!C4:AF37,16,false)="P","F","")& IF(vlookup(BC25,Inventory!C4:AF37,17,false)="P","C","")& IF(vlookup(BC25,Inventory!C4:AF37,18,false)="P","E","")& IF(vlookup(BC25,Inventory!C4:AF37,19,false)="P","A","")& " Proof", IFERROR(IF(vlookup(BC26,Inventory!C4:AF37,21,false)=TRUE,IF(vlookup(BC26,Inventory!C4:AF37,16,false)="P","F","")& IF(vlookup(BC26,Inventory!C4:AF37,17,false)="P","C","")& IF(vlookup(BC26,Inventory!C4:AF37,18,false)="P","E","")& IF(vlookup(BC26,Inventory!C4:AF37,19,false)="P","A","")& " Proof", IFERROR(IF(vlookup(BC27,Inventory!C4:AF37,21,false)=TRUE,IF(vlookup(BC27,Inventory!C4:AF37,16,false)="P","F","")& IF(vlookup(BC27,Inventory!C4:AF37,17,false)="P","C","")& IF(vlookup(BC27,Inventory!C4:AF37,18,false)="P","E","")& IF(vlookup(BC27,Inventory!C4:AF37,19,false)="P","A","")& " Proof", IFERROR(IF(vlookup(BC28,Inventory!C4:AF37,21,false)=TRUE,IF(vlookup(BC28,Inventory!C4:AF37,16,false)="P","F","")& IF(vlookup(BC28,Inventory!C4:AF37,17,false)="P","C","")& IF(vlookup(BC28,Inventory!C4:AF37,18,false)="P","E","")& IF(vlookup(BC28,Inventory!C4:AF37,19,false)="P","A","")& " Proof", IFERROR(IF(vlookup(BC29,Inventory!C4:AF37,21,false)=TRUE,IF(vlookup(BC29,Inventory!C4:AF37,16,false)="P","F","")& IF(vlookup(BC29,Inventory!C4:AF37,17,false)="P","C","")& IF(vlookup(BC29,Inventory!C4:AF37,18,false)="P","E","")& IF(vlookup(BC29,Inventory!C4:AF37,19,false)="P","A","")& " Proof", IFERROR(IF(vlookup(BC30,Inventory!C4:AF37,21,false)=TRUE,IF(vlookup(BC30,Inventory!C4:AF37,16,false)="P","F","")& IF(vlookup(BC30,Inventory!C4:AF37,17,false)="P","C","")& IF(vlookup(BC30,Inventory!C4:AF37,18,false)="P","E","")& IF(vlookup(BC30,Inventory!C4:AF37,19,false)="P","A","")& " Proof", IFERROR(IF(vlookup(BC31,Inventory!C4:AF37,21,false)=TRUE,IF(vlookup(BC31,Inventory!C4:AF37,16,false)="P","F","")& IF(vlookup(BC31,Inventory!C4:AF37,17,false)="P","C","")& IF(vlookup(BC31,Inventory!C4:AF37,18,false)="P","E","")& IF(vlookup(BC31,Inventory!C4:AF37,19,false)="P","A","")& " Proof"),""),),"")),"")),"")),"")),"")),"")),"")),"")),"")
