Workbook
Name BLOCKMOD: Vitals!$J$29
Name FOCUSREGEN: #REF!
Name HEAD: Vitals!$E$3:$G$4
Name Combat: Social!$A$1:$A$1000
Name WEIGHT: #REF!
Name APTMOD: Main!$K$6
Name INT: Main!$F$7
Name LEFTUPPERARM: Vitals!$I$8
Name FOCUS: #REF!
Name REGENMOD: Main!$L$4
Name AGE: Main!$E$14
Name LIFESPAN: Main!$D$14
Name WEIGHT: #REF!
Name Combat: Negative!$A$1:$A$1000
Name SkillsKV: Skills!$R$21
Name BEAUTYMOD: Skills!$X$65
Name CON: Main!$F$6
Name Combat: 'Super Tech'!$A$1:$A$1000
Name LEFTUPPERLEG: Vitals!$G$13:$G$14
Name TOUGHNESS: Main!$H$4
Name PORTRAITURL: 'Sheet Settings'!$D$2
Name CHA: Main!$F$9
Name LEFTLOWERARM: Vitals!$I$11
Name RIGHTLOWERARM: Vitals!$C$11
Name RIGHTUPPERARM: #REF!
Name Combat: Learning!$A$1:$A$1000
Name TOTALKV: Main!$C$2:$D$2
Name REFLEXES: #REF!
Name FOCUSMOD: Main!$K$8
Name KARMA: Main!$J$19:$J$20
Name Combat: Magic!$A$1:$A$1000
Name DEX: Main!$F$5
Name Combat: Combat!$A$1:$A$1000
Name WIS: Main!$F$8
Name SPEEDMOD: Main!$L$6
Name RIGHTLOWERLEG: Vitals!$E$18
Name BEAUTY: Main!$F$12
Name LEFTLOWERLEG: Vitals!$G$18
Name COUNTKV: #REF!
Name Combat: Supernatural!$A$1:$A$1000
Name CHEST: Vitals!$E$8:$G$9
Name MAXFOCUS: #REF!
Name Combat: Utility!$A$1:$A$1000
Name RESISTMOD: Main!$K$4
Name Combat: Natural!$A$1:$A$1000
Name WEIGHT: Inventory!$AI$38
Name STR: Main!$F$4
Name WOUNDSTREATED: Vitals!$I$15
Name WEIGHT: #REF!
Name RIGHTUPPERLEG: Vitals!$E$13:$E$14
Name STRAIN: #REF!

Sheet Main
B2: Valmir Calius | C2: {=Skills!R21+(SUM(F4:F6))*4+(SUM(F7:F9))*8+SUM(Exploits!G3:G52)+vlookup(D12,indirect("SEEDDATA!A:C"),2,false)+ IF(BEAUTY = 1,-12, IF(BEAUTY = 2,-8, IF(BEAUTY = 3,-4, IF(BEAUTY = 4,-4, IF(BEAUTY = 5,0, IF(BEAUTY = 6,+0, IF(BEAUTY = 7,+4, IF(BEAUTY = 8,+4, IF(BEAUTY = 9,+8, IF(BEAUTY = 10,+12,))))))))))+ IF(G2 = "1 - Destitute", -80, IF(G2 = "2 - Impoverished",-60, IF(G2 = "3 - Poor",-40, IF(G2 = "4 - Lower Middle Class",-20, IF(G2 = "5 - Middle Class",0, IF(G2 = "6 - Upper Middle Class",20, IF(G2 = "7 - Upper Class",40, IF(G2 = "8 - Rich",60, IF(G2 = "9 - Super Rich",80, IF(G2 = "10 - Elite",100, 0))))))))))} -> #N/A | E2: 5 - Transcendent | G2: 4 - Lower Middle Class | J2: TRUE | K2: TRUE | L2: TRUE
B3: =IMAGE(PORTRAITURL,2) -> #REF! | C3: KARMIC LEVEL | E3: TECH LEVEL | G3: WEALTH LEVEL
C4: STRENGTH | E4: 4 | F4: =E4-IF((LIFESPAN) = "2 - Normal", IF((AGE)<30,0, IF(AGE < 40,1, IF(AGE < 50,3, IF(AGE < 60,6, IF(AGE < 70,10, IF(AGE < 80,15, IF(AGE < 90,21, IF(AGE < 100,28, IF(AGE < 110,36, IF(AGE < 120,45, IF(AGE < 130,55, IF(AGE < 140,66, IF(AGE < 150,78, IF(AGE < 160,91, IF(AGE < 170,105, IF(AGE < 180,120,136)))))))))))))))), IF((LIFESPAN) = "1 - Short", IF((AGE)<20,0, IF(AGE < 30,1, IF(AGE < 40,3, IF(AGE < 50,6, IF(AGE < 60,10, IF(AGE < 70,15, IF(AGE < 80,21, IF(AGE < 90,28, IF(AGE < 100,36, IF(AGE < 111,45, IF(AGE < 120,55, IF(AGE < 130,66, IF(AGE < 140,78, IF(AGE < 150,91, IF(AGE < 160,105, IF(AGE < 170,120,136)))))))))))))))), IF((LIFESPAN) = "3 - Extended", IF((AGE)<40,0, IF(AGE < 50,1, IF(AGE < 60,3, IF(AGE < 70,6, IF(AGE < 80,10, IF(AGE < 90,15, IF(AGE < 100,21, IF(AGE < 110,28, IF(AGE < 120,36, IF(AGE < 130,45, IF(AGE < 140,55, IF(AGE < 150,66, IF(AGE < 160,78, IF(AGE < 170,91, IF(AGE < 180,105, IF(AGE < 190,120,136)))))))))))))))), IF((LIFESPAN) = "4 - Long", IF((AGE)<50,0, IF(AGE < 60,1, IF(AGE < 70,3, IF(AGE < 80,6, IF(AGE < 90,10, IF(AGE < 100,15, IF(AGE < 110,21, IF(AGE < 120,28, IF(AGE < 130,36, IF(AGE < 140,45, IF(AGE < 150,55, IF(AGE < 160,66, IF(AGE < 170,78, IF(AGE < 180,91, IF(AGE < 190,105, IF(AGE < 200,120,136)))))))))))))))), IF((LIFESPAN) = "5 - Epic", IF((AGE)<80,0, IF(AGE < 90,1, IF(AGE < 100,3, IF(AGE < 110,6, IF(AGE < 120,10, IF(AGE < 130,15, IF(AGE < 140,21, IF(AGE < 150,28, IF(AGE < 160,36, IF(AGE < 170,45, IF(AGE < 180,55, IF(AGE < 190,66, IF(AGE < 200,78, IF(AGE < 210,91, IF(AGE < 220,105, IF(AGE < 230,120,136)))))))))))))))), IF((LIFESPAN) = "6 - Immortal", 0,0)))))) -> 4 | G4: 3 | H4: =(STR)+G4 -> 7 | I4: TOUGHNESS | K4: 12 | L4: 2
C5: DEXTERITY | E5: 4 | F5: =E5-IF((LIFESPAN) = "2 - Normal", IF((AGE)<40,0, IF(AGE < 50,1, IF(AGE < 60,3, IF(AGE < 70,6, IF(AGE < 80,10, IF(AGE < 90,15, IF(AGE < 100,21, IF(AGE < 110,28, IF(AGE < 120,36, IF(AGE < 130,45, IF(AGE < 140,55, IF(AGE < 150,66, IF(AGE < 160,78, IF(AGE < 170,91, IF(AGE < 180,105,120))))))))))))))), IF((LIFESPAN) = "1 - Short", IF((AGE)<30,0, IF(AGE < 40,1, IF(AGE < 50,3, IF(AGE < 60,6, IF(AGE < 70,10, IF(AGE < 80,15, IF(AGE < 90,21, IF(AGE < 100,28, IF(AGE < 110,36, IF(AGE < 120,45, IF(AGE < 130,55, IF(AGE < 140,66, IF(AGE < 150,78, IF(AGE < 160,91, IF(AGE < 170,105, IF(AGE < 180,120,136)))))))))))))))), IF((LIFESPAN) = "3 - Extended", IF((AGE)<50,0, IF(AGE < 60,1, IF(AGE < 70,3, IF(AGE < 80,6, IF(AGE < 90,10, IF(AGE < 100,15, IF(AGE < 110,21, IF(AGE < 120,28, IF(AGE < 130,36, IF(AGE < 140,45, IF(AGE < 150,55, IF(AGE < 160,66, IF(AGE < 170,78, IF(AGE < 180,91, IF(AGE < 190,105,120))))))))))))))), IF((LIFESPAN) = "4 - Long", IF((AGE)<60,0, IF(AGE < 70,1, IF(AGE < 80,3, IF(AGE < 90,6, IF(AGE < 100,10, IF(AGE < 110,15, IF(AGE < 120,21, IF(AGE < 130,28, IF(AGE < 140,36, IF(AGE < 150,45, IF(AGE < 160,55, IF(AGE < 170,66, IF(AGE < 180,78, IF(AGE < 190,91, IF(AGE < 200,105,120))))))))))))))), IF((LIFESPAN) = "5 - Epic", IF((AGE)<90,0, IF(AGE < 100,1, IF(AGE < 110,3, IF(AGE < 120,6, IF(AGE < 130,10, IF(AGE < 140,15, IF(AGE < 150,21, IF(AGE < 160,28, IF(AGE < 170,36, IF(AGE < 180,45, IF(AGE < 190,55, IF(AGE < 200,66, IF(AGE < 210,78, IF(AGE < 220,91, IF(AGE < 230,105,120))))))))))))))), IF((LIFESPAN) = "6 - Immortal", 0,0)))))) -> 4 | G5: 5 | H5: =(DEX)+G5-Vitals!BS30 -> 7 | I5: NIMBLENESS | K5: BASE RESIST | L5: BASE HEALING
C6: CONSTITUTION | E6: 4 | F6: =E6-IF((LIFESPAN) = "2 - Normal", IF((AGE)<50,0, IF(AGE < 60,1, IF(AGE < 70,3, IF(AGE < 80,6, IF(AGE < 90,10, IF(AGE < 100,15, IF(AGE < 110,21, IF(AGE < 120,28, IF(AGE < 130,36, IF(AGE < 140,45, IF(AGE < 150,55, IF(AGE < 160,66, IF(AGE < 170,78, IF(AGE < 180,91,136)))))))))))))), IF((LIFESPAN) = "1 - Short", IF((AGE)<40,0, IF(AGE < 50,1, IF(AGE < 60,3, IF(AGE < 70,6, IF(AGE < 80,10, IF(AGE < 90,15, IF(AGE < 100,21, IF(AGE < 110,28, IF(AGE < 120,36, IF(AGE < 130,45, IF(AGE < 140,55, IF(AGE < 150,66, IF(AGE < 160,78, IF(AGE < 170,91, IF(AGE < 180,105, IF(AGE < 190,120,136)))))))))))))))), IF((LIFESPAN) = "3 - Extended", IF((AGE)<60,0, IF(AGE < 70,1, IF(AGE < 80,3, IF(AGE < 90,6, IF(AGE < 100,10, IF(AGE < 110,15, IF(AGE < 120,21, IF(AGE < 130,28, IF(AGE < 140,36, IF(AGE < 150,45, IF(AGE < 160,55, IF(AGE < 170,66, IF(AGE < 180,78, IF(AGE < 190,91,136)))))))))))))), IF((LIFESPAN) = "4 - Long", IF((AGE)<70,0, IF(AGE < 80,1, IF(AGE < 90,3, IF(AGE < 100,6, IF(AGE < 110,10, IF(AGE < 120,15, IF(AGE < 130,21, IF(AGE < 140,28, IF(AGE < 150,36, IF(AGE < 160,45, IF(AGE < 170,55, IF(AGE < 180,66, IF(AGE < 190,78, IF(AGE < 200,91,120)))))))))))))), IF((LIFESPAN) = "5 - Epic", IF((AGE)<100,0, IF(AGE < 110,1, IF(AGE < 120,3, IF(AGE < 130,6, IF(AGE < 140,10, IF(AGE < 150,15, IF(AGE < 160,21, IF(AGE < 170,28, IF(AGE < 180,36, IF(AGE < 190,45, IF(AGE < 200,55, IF(AGE < 210,66, IF(AGE < 220,78, IF(AGE < 230,91,120)))))))))))))), IF((LIFESPAN) = "6 - Immortal", 0,0)))))) -> 4 | G6: 5 | H6: =(CON)+G6 -> 9 | I6: VIRILITY | K6: 2 | L6: 0
C7: INTELLIGENCE | E7: 14 | F7: =E7-IF((LIFESPAN) = "2 - Normal", IF((AGE)<60,0, IF(AGE < 70,1, IF(AGE < 80,3, IF(AGE < 90,6, IF(AGE < 100,10, IF(AGE < 110,15, IF(AGE < 120,21, IF(AGE < 130,28, IF(AGE < 140,36, IF(AGE < 150,45, IF(AGE < 160,55, IF(AGE < 170,66, IF(AGE < 180,78,105))))))))))))), IF((LIFESPAN) = "1 - Short", IF((AGE)<50,0, IF(AGE < 40,1, IF(AGE < 50,3, IF(AGE < 60,6, IF(AGE < 70,10, IF(AGE < 80,15, IF(AGE < 90,21, IF(AGE < 100,28, IF(AGE < 110,36, IF(AGE < 120,45, IF(AGE < 130,55, IF(AGE < 140,66, IF(AGE < 150,78, IF(AGE < 160,91, IF(AGE < 170,105, IF(AGE < 180,120,136)))))))))))))))), IF((LIFESPAN) = "3 - Extended", IF((AGE)<70,0, IF(AGE < 80,1, IF(AGE < 90,3, IF(AGE < 100,6, IF(AGE < 110,10, IF(AGE < 120,15, IF(AGE < 130,21, IF(AGE < 140,28, IF(AGE < 150,36, IF(AGE < 160,45, IF(AGE < 170,55, IF(AGE < 180,66, IF(AGE < 190,78,136))))))))))))), IF((LIFESPAN) = "4 - Long", IF((AGE)<70,0, IF(AGE < 80,1, IF(AGE < 90,3, IF(AGE < 100,6, IF(AGE < 110,10, IF(AGE < 120,15, IF(AGE < 130,21, IF(AGE < 140,28, IF(AGE < 150,36, IF(AGE < 160,45, IF(AGE < 170,55, IF(AGE < 180,66, IF(AGE < 190,78, IF(AGE < 200,91,120)))))))))))))), IF((LIFESPAN) = "5 - Epic", IF((AGE)<100,0, IF(AGE < 110,1, IF(AGE < 120,3, IF(AGE < 130,6, IF(AGE < 140,10, IF(AGE < 150,15, IF(AGE < 160,21, IF(AGE < 170,28, IF(AGE < 180,36, IF(AGE < 190,45, IF(AGE < 200,55, IF(AGE < 210,66, IF(AGE < 220,78, IF(AGE < 230,91,120)))))))))))))), IF((LIFESPAN) = "6 - Immortal", 0,0)))))) -> 14 | G7: 5 | H7: =(INT)+G7 -> 19 | I7: WIT | K7: BASE APT | L7: SPEED MOD
C8: WISDOM | E8: 4 | F8: =E8-IF((LIFESPAN) = "2 - Normal", IF((AGE)<70,0, IF(AGE < 80,1, IF(AGE < 90,3, IF(AGE < 100,6, IF(AGE < 110,10, IF(AGE < 120,15, IF(AGE < 130,21, IF(AGE < 140,28, IF(AGE < 150,36, IF(AGE < 160,45, IF(AGE < 170,55, IF(AGE < 180,66,105)))))))))))), IF((LIFESPAN) = "1 - Short", IF((AGE)<60,0, IF(AGE < 70,1, IF(AGE < 80,3, IF(AGE < 90,6, IF(AGE < 100,10, IF(AGE < 110,15, IF(AGE < 120,21, IF(AGE < 130,28, IF(AGE < 140,36, IF(AGE < 150,45, IF(AGE < 160,55, IF(AGE < 170,66, IF(AGE < 180,78, IF(AGE < 190,91, IF(AGE < 200,105, IF(AGE < 210,120,136)))))))))))))))), IF((LIFESPAN) = "3 - Extended", IF((AGE)<80,0, IF(AGE < 90,1, IF(AGE < 100,3, IF(AGE < 110,6, IF(AGE < 120,10, IF(AGE < 130,15, IF(AGE < 140,21, IF(AGE < 150,28, IF(AGE < 160,36, IF(AGE < 170,45, IF(AGE < 180,55, IF(AGE < 190,66,136)))))))))))), IF((LIFESPAN) = "4 - Long", IF((AGE)<80,0, IF(AGE < 90,1, IF(AGE < 100,3, IF(AGE < 110,6, IF(AGE < 120,10, IF(AGE < 130,15, IF(AGE < 140,21, IF(AGE < 150,28, IF(AGE < 160,36, IF(AGE < 170,45, IF(AGE < 180,55, IF(AGE < 190,66, IF(AGE < 200,78,120))))))))))))), IF((LIFESPAN) = "5 - Epic", IF((AGE)<110,0, IF(AGE < 120,1, IF(AGE < 130,3, IF(AGE < 140,6, IF(AGE < 150,10, IF(AGE < 160,15, IF(AGE < 170,21, IF(AGE < 180,28, IF(AGE < 190,36, IF(AGE < 200,45, IF(AGE < 210,55, IF(AGE < 220,66, IF(AGE < 230,78,120))))))))))))), IF((LIFESPAN) = "6 - Immortal", 0,0)))))) -> 4 | G8: 5 | H8: =(WIS)+G8 -> 9 | I8: INGENUITY | K8: 34 | L8: 0
C9: CHARISMA | E9: 10 | F9: =E9-IF((LIFESPAN) = "2 - Normal", IF((AGE)<80,0, IF(AGE < 90,1, IF(AGE < 100,3, IF(AGE < 110,6, IF(AGE < 120,10, IF(AGE < 130,15, IF(AGE < 140,21, IF(AGE < 150,28, IF(AGE < 160,36, IF(AGE < 170,45, IF(AGE < 180,55,105))))))))))), IF((LIFESPAN) = "1 - Short", IF((AGE)<70,0, IF(AGE < 80,1, IF(AGE < 90,3, IF(AGE < 100,6, IF(AGE < 110,10, IF(AGE < 120,15, IF(AGE < 130,21, IF(AGE < 140,28, IF(AGE < 150,36, IF(AGE < 160,45, IF(AGE < 170,55, IF(AGE < 180,66, IF(AGE < 190,78, IF(AGE < 200,91, IF(AGE < 210,105, IF(AGE < 220,120,136)))))))))))))))), IF((LIFESPAN) = "3 - Extended", IF((AGE)<90,0, IF(AGE < 100,1, IF(AGE < 110,3, IF(AGE < 120,6, IF(AGE < 130,10, IF(AGE < 140,15, IF(AGE < 150,21, IF(AGE < 160,28, IF(AGE < 170,36, IF(AGE < 180,45, IF(AGE < 190,55,136))))))))))), IF((LIFESPAN) = "4 - Long", IF((AGE)<90,0, IF(AGE < 100,1, IF(AGE < 110,3, IF(AGE < 120,6, IF(AGE < 130,10, IF(AGE < 140,15, IF(AGE < 150,21, IF(AGE < 160,28, IF(AGE < 170,36, IF(AGE < 180,45, IF(AGE < 190,55, IF(AGE < 200,66,120)))))))))))), IF((LIFESPAN) = "5 - Epic", IF((AGE)<120,0, IF(AGE < 130,1, IF(AGE < 140,3, IF(AGE < 150,6, IF(AGE < 160,10, IF(AGE < 170,15, IF(AGE < 180,21, IF(AGE < 190,28, IF(AGE < 200,36, IF(AGE < 210,45, IF(AGE < 220,55, IF(AGE < 230,66,120)))))))))))), IF((LIFESPAN) = "6 - Immortal", 0,0)))))) -> 10 | G9: 7 | H9: =(CHA)+G9 -> 17 | I9: CONVICTION | K9: BASE ENDURANCE | L9: UNARMED MOD
D10: ATTRIBUTES | E10: LEVEL | F10: SCORE | G10: SAVE MODS | H10: SAVES | K10: MODS
D12: Neo-Human | E12: Male | F12: 11 | G12: Kether | J12: 6' | K12: 190 | L12: Black/Blue
D13: SEED | E13: SEX | F13: BEAUTY | G13: HOME | J13: HEIGHT | K13: WEIGHT | L13: HAIR & EYES
D14: 6 - Immortal | E14: 5505 | F14: 7th | G14: 1 | H14: None | J14: Well kept
D15: LIFE SPAN | E15: AGE | F15: BIRTH MONTH | G15: BIRTH DAY | H15: MONKEY PAW
J17: APPEARANCE
D19: We must evolve or die. When you find a weakness, overcome it or exploit it. | J19: 25
D21: Magic and technology can be melded perfectly. Find a way to make it happen.
D22: GOALS & VALUES | J22: KARMA

Sheet Skills
C1: Basic Skills | Q1: Magic Skills
C2: SKILLS | D2: LEVEL | E2: GOVERNING ATTRIBUTES | I2: MODS | J2: SKILL CHECK | K2: EPA | L2: MAX SKILL | M2: FAILED | Q2: SKILLS | R2: LEVEL | S2: FOCUS | T2: MODS | U2: SKILL CHECK | V2: FPA | W2: MAX SKILL | X2: FAILED
C4: ATHLETICS | Q4: PILLAR OF MERCY
C5: Swim | D5: 2 | E5: STR CON | F5: =STR -> 4 | G5: =CON -> 4 | J5: =IF(AND(D5 < 4, D5 > 1)," Coin", IF(AND(D5 < 20, D5 > 12)," d12", IF(D5 = 0, "No Skill", IF(D5 = 1, 1, " d" & 2*ROUNDDOWN(D5/2,0))))) & IF(I5>0,"+"&I5,I5) -> Coin | K5: =MIN(F5,G5,H5) -> 4 | L5: =D5+I5 -> 2 | M5: NO | Q5: Alteration | R5: 0 | S5: 0 | T5: 2 | U5: =IF(AND(R5 < 4, R5 > 1)," Coin", IF(AND(R5 < 20, R5 > 12)," d12", IF(R5 = 0, "No Skill", IF(R5 = 1, 1, " d" & 2*ROUNDDOWN(R5/2,0))))) & IF(T5>0,"+"&T5,T5) -> No Skill+2 | V5: =IF(S5>0,S5,IF(R19="Mercy",10,IF(R19="Severity",0,5))) -> 5 | W5: =R5+R17+R18+T5 -> 2 | X5: NO
C6: Sneak | D6: 4 | E6: DEX WIS | F6: =DEX -> 4 | G6: =WIS -> 4 | J6: =IF(AND(D6 < 4, D6 > 1)," Coin", IF(AND(D6 < 20, D6 > 12)," d12", IF(D6 = 0, "No Skill", IF(D6 = 1, 1, " d" & 2*ROUNDDOWN(D6/2,0))))) & IF(I6>0,"+"&I6,I6) -> d4 | K6: =MIN(F6,G6,H6) -> 4 | L6: =D6+I6 -> 4 | M6: NO | Q6: Restoration | R6: 0 | S6: 0 | T6: 2 | U6: =IF(AND(R6 < 4, R6 > 1)," Coin", IF(AND(R6 < 20, R6 > 12)," d12", IF(R6 = 0, "No Skill", IF(R6 = 1, 1, " d" & 2*ROUNDDOWN(R6/2,0))))) & IF(T6>0,"+"&T6,T6) -> No Skill+2 | V6: =IF(S6>0,S6,IF(R19="Mercy",10,IF(R19="Severity",0,5))) -> 5 | W6: =R6+R17+R18+T6 -> 2 | X6: NO
C7: Manual Dexterity | D7: 6 | E7: STR DEX | F7: =STR -> 4 | G7: =DEX -> 4 | J7: =IF(AND(D7 < 4, D7 > 1)," Coin", IF(AND(D7 < 20, D7 > 12)," d12", IF(D7 = 0, "No Skill", IF(D7 = 1, 1, " d" & 2*ROUNDDOWN(D7/2,0))))) & IF(I7>0,"+"&I7,I7) -> d6 | K7: =MIN(F7,G7,H7) -> 4 | L7: =D7+I7 -> 6 | M7: NO | Q7: Enchantment | R7: 0 | S7: 0 | T7: 2 | U7: =IF(AND(R7 < 4, R7 > 1)," Coin", IF(AND(R7 < 20, R7 > 12)," d12", IF(R7 = 0, "No Skill", IF(R7 = 1, 1, " d" & 2*ROUNDDOWN(R7/2,0))))) & IF(T7>0,"+"&T7,T7) -> No Skill+2 | V7: =IF(S7>0,S7,IF(R19="Mercy",10,IF(R19="Severity",0,5))) -> 5 | W7: =R7+R17+R18+T7 -> 2 | X7: NO
C8: Climb | D8: 4 | E8: STR DEX CON | F8: =STR -> 4 | G8: =DEX -> 4 | H8: =CON -> 4 | J8: =IF(AND(D8 < 4, D8 > 1)," Coin", IF(AND(D8 < 20, D8 > 12)," d12", IF(D8 = 0, "No Skill", IF(D8 = 1, 1, " d" & 2*ROUNDDOWN(D8/2,0))))) & IF(I8>0,"+"&I8,I8) -> d4 | K8: =MIN(F8,G8,H8) -> 4 | L8: =D8+I8 -> 4 | M8: NO | Q8: PILLAR OF BALANCE
C9: Acrobatics | D9: 2 | E9: STR DEX CHA | F9: =STR -> 4 | G9: =DEX -> 4 | H9: =CHA -> 10 | J9: =IF(AND(D9 < 4, D9 > 1)," Coin", IF(AND(D9 < 20, D9 > 12)," d12", IF(D9 = 0, "No Skill", IF(D9 = 1, 1, " d" & 2*ROUNDDOWN(D9/2,0))))) & IF(I9>0,"+"&I9,I9) -> Coin | K9: =MIN(F9,G9,H9) -> 4 | L9: =D9+I9 -> 2 | M9: NO | Q9: Divination | R9: 0 | S9: 0 | T9: 2 | U9: =IF(AND(R9 < 4, R9 > 1)," Coin", IF(AND(R9 < 20, R9 > 12)," d12", IF(R9 = 0, "No Skill", IF(R9 = 1, 1, " d" & 2*ROUNDDOWN(R9/2,0))))) & IF(T9>0,"+"&T9,T9) -> No Skill+2 | V9: =IF(S9>0,S9,IF(R19="Mercy",5,IF(R19="Severity",5,5))) -> 5 | W9: =R9+R17+R18+T9 -> 2 | X9: NO
C10: SOCIAL SKILLS | Q10: Dissolution | R10: 0 | S10: 0 | T10: 2 | U10: =IF(AND(R10 < 4, R10 > 1)," Coin", IF(AND(R10 < 20, R10 > 12)," d12", IF(R10 = 0, "No Skill", IF(R10 = 1, 1, " d" & 2*ROUNDDOWN(R10/2,0))))) & IF(T10>0,"+"&T10,T10) -> No Skill+2 | V10: =IF(S10>0,S10,IF(R19="Mercy",5,IF(R19="Severity",5,5))) -> 5 | W10: =R10+R17+R18+T10 -> 2 | X10: NO
C11: Seduction | D11: 5 | E11: WIS CHA | F11: =WIS -> 4 | G11: =CHA -> 10 | J11: =IF(AND(D11 < 4, D11 > 1)," Coin", IF(AND(D11 < 20, D11 > 12)," d12", IF(D11 = 0, "No Skill", IF(D11 = 1, 1, " d" & 2*ROUNDDOWN(D11/2,0))))) & IF(I11>0,"+"&I11,I11) & IF(BEAUTYMOD > 0,"+" & BEAUTYMOD, "-" & BEAUTYMOD*-1) -> d4+3 | K11: =MIN(F11,G11,H11) -> 4 | L11: =BEAUTYMOD+I11+D11 -> 8 | M11: NO | Q11: Abjuration | R11: 0 | S11: 0 | T11: 2 | U11: =IF(AND(R11 < 4, R11 > 1)," Coin", IF(AND(R11 < 20, R11 > 12)," d12", IF(R11 = 0, "No Skill", IF(R11 = 1, 1, " d" & 2*ROUNDDOWN(R11/2,0))))) & IF(T11>0,"+"&T11,T11) -> No Skill+2 | V11: =IF(S11>0,S11,IF(R19="Mercy",5,IF(R19="Severity",5,5))) -> 5 | W11: =R11+R17+R18+T11 -> 2 | X11: NO
C12: Intimidation | D12: 5 | E12: STR CHA | F12: =STR -> 4 | G12: =CHA -> 10 | J12: =IF(AND(D12 < 4, D12 > 1)," Coin", IF(AND(D12 < 20, D12 > 12)," d12", IF(D12 = 0, "No Skill", IF(D12 = 1, 1, " d" & 2*ROUNDDOWN(D12/2,0))))) & IF(I12>0,"+"&I12,I12) & IF(BEAUTYMOD > 0,"-" & BEAUTYMOD, "+" & BEAUTYMOD*-1) -> d4-3 | K12: =MIN(F12,G12,H12) -> 4 | L12: =(BEAUTYMOD*-1)+I12+D12 -> 2 | M12: NO | Q12: Illusion | R12: 0 | S12: 0 | T12: 2 | U12: =IF(AND(R12 < 4, R12 > 1)," Coin", IF(AND(R12 < 20, R12 > 12)," d12", IF(R12 = 0, "No Skill", IF(R12 = 1, 1, " d" & 2*ROUNDDOWN(R12/2,0))))) & IF(T12>0,"+"&T12,T12) -> No Skill+2 | V12: =IF(S12>0,S12,IF(R19="Mercy",5,IF(R19="Severity",5,5))) -> 5 | W12: =R12+R17+R18+T12 -> 2 | X12: NO
C13: Negotiation | D13: 12 | E13: INT CHA | F13: =INT -> 14 | G13: =CHA -> 10 | J13: =IF(AND(D13 < 4, D13 > 1)," Coin", IF(AND(D13 < 20, D13 > 12)," d12", IF(D13 = 0, "No Skill", IF(D13 = 1, 1, " d" & 2*ROUNDDOWN(D13/2,0))))) & IF(I13>0,"+"&I13,I13) & IF(BEAUTYMOD > 0,"+" & BEAUTYMOD, "-" & BEAUTYMOD*-1) -> d12+3 | K13: =MIN(F13,G13,H13) -> 10 | L13: =BEAUTYMOD+I13+D13 -> 15 | M13: NO | Q13: PILLAR OF SEVERITY
C14: Deception | D14: 12 | E14: INT WIS | F14: =INT -> 14 | G14: =WIS -> 4 | J14: =IF(AND(D14 < 4, D14 > 1)," Coin", IF(AND(D14 < 20, D14 > 12)," d12", IF(D14 = 0, "No Skill", IF(D14 = 1, 1, " d" & 2*ROUNDDOWN(D14/2,0))))) & IF(I14>0,"+"&I14,I14) -> d12 | K14: =MIN(F14,G14,H14) -> 4 | L14: =D14+I14 -> 12 | M14: NO | Q14: Fortune | R14: 0 | S14: 0 | T14: 2 | U14: =IF(AND(R14 < 4, R14 > 1)," Coin", IF(AND(R14 < 20, R14 > 12)," d12", IF(R14 = 0, "No Skill", IF(R14 = 1, 1, " d" & 2*ROUNDDOWN(R14/2,0))))) & IF(T14>0,"+"&T14,T14) -> No Skill+2 | V14: =IF(S14>0,S14,IF(R19="Mercy",0,IF(R19="Severity",10,5))) -> 5 | W14: =R14+R17+R18+T14 -> 2 | X14: NO
C15: Leadership | D15: 12 | E15: INT WIS CHA | F15: =INT -> 14 | G15: =WIS -> 4 | H15: =CHA -> 10 | J15: =IF(AND(D15 < 4, D15 > 1)," Coin", IF(AND(D15 < 20, D15 > 12)," d12", IF(D15 = 0, "No Skill", IF(D15 = 1, 1, " d" & 2*ROUNDDOWN(D15/2,0))))) & IF(I15>0,"+"&I15,I15) -> d12 | K15: =MIN(F15,G15,H15) -> 4 | L15: =D15+I15 -> 12 | M15: NO | Q15: Force | R15: 0 | S15: 15 | T15: 2 | U15: =IF(AND(R15 < 4, R15 > 1)," Coin", IF(AND(R15 < 20, R15 > 12)," d12", IF(R15 = 0, "No Skill", IF(R15 = 1, 1, " d" & 2*ROUNDDOWN(R15/2,0))))) & IF(T15>0,"+"&T15,T15) -> No Skill+2 | V15: =IF(S15>0,S15,IF(R19="Mercy",0,IF(R19="Severity",10,5))) -> 15 | W15: =R15+R17+R18+T15 -> 2 | X15: NO
C16: MARTIAL ARTS | Q16: Conjuration | R16: 0 | S16: 0 | T16: 2 | U16: =IF(AND(R16 < 4, R16 > 1)," Coin", IF(AND(R16 < 20, R16 > 12)," d12", IF(R16 = 0, "No Skill", IF(R16 = 1, 1, " d" & 2*ROUNDDOWN(R16/2,0))))) & IF(T16>0,"+"&T16,T16) -> No Skill+2 | V16: =IF(S16>0,S16,IF(R19="Mercy",0,IF(R19="Severity",10,5))) -> 5 | W16: =R16+R17+R18+T16 -> 2 | X16: NO
C17: Blades | D17: 2 | E17: STR DEX | F17: =STR -> 4 | G17: =DEX -> 4 | J17: =IF(AND(D17 < 4, D17 > 1)," Coin", IF(AND(D17 < 20, D17 > 12)," d12", IF(D17 = 0, "No Skill", IF(D17 = 1, 1, " d" & 2*ROUNDDOWN(D17/2,0))))) & IF(I17>0,"+"&I17,I17) -> Coin | K17: =MIN(F17,G17,H17) -> 4 | L17: =D17+I17 -> 2 | M17: NO | Q17: BODY MANA | R17: 0
C18: Polearms | D18: 0 | E18: STR DEX | F18: =STR -> 4 | G18: =DEX -> 4 | J18: =IF(AND(D18 < 4, D18 > 1)," Coin", IF(AND(D18 < 20, D18 > 12)," d12", IF(D18 = 0, "No Skill", IF(D18 = 1, 1, " d" & 2*ROUNDDOWN(D18/2,0))))) & IF(I18>0,"+"&I18,I18) -> No Skill | K18: =MIN(F18,G18,H18) -> 4 | L18: =D18+I18 -> 0 | M18: NO | Q18: CATALYST MANA | R18: 0 | T18: UNIQUE RESOURCES | U18: Nano Memory | V18: 15 | W18: 15
C19: Hammers & Axes | D19: 8 | E19: STR CON | F19: =STR -> 4 | G19: =CON -> 4 | J19: =IF(AND(D19 < 4, D19 > 1)," Coin", IF(AND(D19 < 20, D19 > 12)," d12", IF(D19 = 0, "No Skill", IF(D19 = 1, 1, " d" & 2*ROUNDDOWN(D19/2,0))))) & IF(I19>0,"+"&I19,I19) -> d8 | K19: =MIN(F19,G19,H19) -> 4 | L19: =D19+I19 -> 8 | M19: NO | Q19: ATTUNEMENT | R19: None | U19: Nano Energy | V19: 30 | W19: 9
C20: Firearms | D20: 20 | E20: DEX CHA | F20: =DEX -> 4 | G20: =CHA -> 10 | J20: =IF(AND(D20 < 4, D20 > 1)," Coin", IF(AND(D20 < 20, D20 > 12)," d12", IF(D20 = 0, "No Skill", IF(D20 = 1, 1, " d" & 2*ROUNDDOWN(D20/2,0))))) & IF(I20>0,"+"&I20,I20) -> d20 | K20: =MIN(F20,G20,H20) -> 4 | L20: =D20+I20 -> 20 | M20: NO | Q20: TRAINABLE SKILLS | R20: =MAX(Main!H7,1) -> 19
C21: Exotic Weapons | D21: 2 | E21: STR DEX WIS | F21: =STR -> 4 | G21: =DEX -> 4 | H21: =WIS -> 4 | J21: =IF(AND(D21 < 4, D21 > 1)," Coin", IF(AND(D21 < 20, D21 > 12)," d12", IF(D21 = 0, "No Skill", IF(D21 = 1, 1, " d" & 2*ROUNDDOWN(D21/2,0))))) & IF(I21>0,"+"&I21,I21) -> Coin | K21: =MIN(F21,G21,H21) -> 4 | L21: =D21+I21 -> 2 | M21: NO | Q21: SKILLS KV | R21: =FLOOR(SUM(D5:D9,D11:D15,D17:D23,D25:D27,D29:D31,D33:D36,D38:D42,D44:D48,D50:D53,D55:D57,D59:D61,D63:D65)+SUM(R5:R7,R9:R12,R14:R16)*2,1) -> 404
C22: Archery | D22: 0 | E22: DEX CON WIS | F22: =DEX -> 4 | G22: =CON -> 4 | H22: =WIS -> 4 | J22: =IF(AND(D22 < 4, D22 > 1)," Coin", IF(AND(D22 < 20, D22 > 12)," d12", IF(D22 = 0, "No Skill", IF(D22 = 1, 1, " d" & 2*ROUNDDOWN(D22/2,0))))) & IF(I22>0,"+"&I22,I22) -> No Skill | K22: =MIN(F22,G22,H22) -> 4 | L22: =D22+I22 -> 0 | M22: NO
C23: Unarmed | D23: 20 | E23: STR DEX CON | F23: =STR -> 4 | G23: =DEX -> 4 | H23: =CON -> 4 | J23: =IF(AND(D23 < 4, D23 > 1)," Coin", IF(AND(D23 < 20, D23 > 12)," d12", IF(D23 = 0, "No Skill", IF(D23 = 1, 1, " d" & 2*ROUNDDOWN(D23/2,0))))) & IF(I23>0,"+"&I23,I23) -> d20 | K23: =MIN(F23,G23,H23) -> 4 | L23: =D23+I23 -> 20 | M23: NO | Q23: PASSIVE TASKS
C24: PERFORMING ARTS | R24: TYPE | T24: TIME | U24: NOTES
C25: Music | D25: 4 | E25: INT WIS | F25: =INT -> 14 | G25: =WIS -> 4 | J25: =IF(AND(D25 < 4, D25 > 1)," Coin", IF(AND(D25 < 20, D25 > 12)," d12", IF(D25 = 0, "No Skill", IF(D25 = 1, 1, " d" & 2*ROUNDDOWN(D25/2,0))))) & IF(I25>0,"+"&I25,I25) & IF(BEAUTYMOD > 0,"+" & BEAUTYMOD, "-" & BEAUTYMOD*-1) -> d4+3 | K25: =MIN(F25,G25,H25) -> 4 | L25: =BEAUTYMOD+I25+D25 -> 7 | M25: NO | R25: Practice | U25: Manual Dex
C26: Drama | D26: 0 | E26: DEX WIS CHA | F26: =DEX -> 4 | G26: =WIS -> 4 | H26: =CHA -> 10 | J26: =IF(AND(D26 < 4, D26 > 1)," Coin", IF(AND(D26 < 20, D26 > 12)," d12", IF(D26 = 0, "No Skill", IF(D26 = 1, 1, " d" & 2*ROUNDDOWN(D26/2,0))))) & IF(I26>0,"+"&I26,I26) & IF(BEAUTYMOD > 0,"+" & BEAUTYMOD, "-" & BEAUTYMOD*-1) -> No Skill+3 | K26: =MIN(F26,G26,H26) -> 4 | L26: =BEAUTYMOD+I26+D26 -> 3 | M26: NO
C27: Dance | D27: 0 | E27: STR DEX CHA | F27: =STR -> 4 | G27: =DEX -> 4 | H27: =CHA -> 10 | J27: =IF(AND(D27 < 4, D27 > 1)," Coin", IF(AND(D27 < 20, D27 > 12)," d12", IF(D27 = 0, "No Skill", IF(D27 = 1, 1, " d" & 2*ROUNDDOWN(D27/2,0))))) & IF(I27>0,"+"&I27,I27) & IF(BEAUTYMOD > 0,"+" & BEAUTYMOD, "-" & BEAUTYMOD*-1) -> No Skill+3 | K27: =MIN(F27,G27,H27) -> 4 | L27: =BEAUTYMOD+I27+D27 -> 3 | M27: NO
C28: VISUAL ARTS | Q28: STATUS EFFECTS
C29: Sculpt | D29: 16 | E29: DEX WIS CHA | F29: =DEX -> 4 | G29: =WIS -> 4 | H29: =CHA -> 10 | J29: =IF(AND(D29 < 4, D29 > 1)," Coin", IF(AND(D29 < 20, D29 > 12)," d12", IF(D29 = 0, "No Skill", IF(D29 = 1, 1, " d" & 2*ROUNDDOWN(D29/2,0))))) & IF(I29>0,"+"&I29,I29) -> d12 | K29: =MIN(F29,G29,H29) -> 4 | L29: =D29+I29 -> 16 | M29: NO
C30: Paint & Draw | D30: 0 | E30: DEX WIS CHA | F30: =DEX -> 4 | G30: =WIS -> 4 | H30: =CHA -> 10 | J30: =IF(AND(D30 < 4, D30 > 1)," Coin", IF(AND(D30 < 20, D30 > 12)," d12", IF(D30 = 0, "No Skill", IF(D30 = 1, 1, " d" & 2*ROUNDDOWN(D30/2,0))))) & IF(I30>0,"+"&I30,I30) -> No Skill | K30: =MIN(F30,G30,H30) -> 4 | L30: =D30+I30 -> 0 | M30: NO
C31: Literature | D31: 4 | E31: INT WIS CHA | F31: =INT -> 14 | G31: =WIS -> 4 | H31: =CHA -> 10 | J31: =IF(AND(D31 < 4, D31 > 1)," Coin", IF(AND(D31 < 20, D31 > 12)," d12", IF(D31 = 0, "No Skill", IF(D31 = 1, 1, " d" & 2*ROUNDDOWN(D31/2,0))))) & IF(I31>0,"+"&I31,I31) -> d4 | K31: =MIN(F31,G31,H31) -> 4 | L31: =D31+I31 -> 4 | M31: NO
C32: SOCIAL SCIENCES
C33: History | D33: 4 | E33: INT CHA | F33: =INT -> 14 | G33: =CHA -> 10 | J33: =IF(AND(D33 < 4, D33 > 1)," Coin", IF(AND(D33 < 20, D33 > 12)," d12", IF(D33 = 0, "No Skill", IF(D33 = 1, 1, " d" & 2*ROUNDDOWN(D33/2,0))))) & IF(I33>0,"+"&I33,I33) -> d4 | K33: =MIN(F33,G33,H33) -> 10 | L33: =D33+I33 -> 4 | M33: NO
C34: Economics | D34: 4 | E34: WIS CHA | F34: =WIS -> 4 | G34: =CHA -> 10 | J34: =IF(AND(D34 < 4, D34 > 1)," Coin", IF(AND(D34 < 20, D34 > 12)," d12", IF(D34 = 0, "No Skill", IF(D34 = 1, 1, " d" & 2*ROUNDDOWN(D34/2,0))))) & IF(I34>0,"+"&I34,I34) -> d4 | K34: =MIN(F34,G34,H34) -> 4 | L34: =D34+I34 -> 4 | M34: NO
C35: Geography | D35: 1 | E35: INT CHA | F35: =INT -> 14 | G35: =CHA -> 10 | J35: =IF(AND(D35 < 4, D35 > 1)," Coin", IF(AND(D35 < 20, D35 > 12)," d12", IF(D35 = 0, "No Skill", IF(D35 = 1, 1, " d" & 2*ROUNDDOWN(D35/2,0))))) & IF(I35>0,"+"&I35,I35) -> 1 | K35: =MIN(F35,G35,H35) -> 10 | L35: =D35+I35 -> 1 | M35: NO
C36: Law | D36: 1 | E36: INT WIS CHA | F36: =INT -> 14 | G36: =WIS -> 4 | H36: =CHA -> 10 | J36: =IF(AND(D36 < 4, D36 > 1)," Coin", IF(AND(D36 < 20, D36 > 12)," d12", IF(D36 = 0, "No Skill", IF(D36 = 1, 1, " d" & 2*ROUNDDOWN(D36/2,0))))) & IF(I36>0,"+"&I36,I36) -> 1 | K36: =MIN(F36,G36,H36) -> 4 | L36: =D36+I36 -> 1 | M36: NO
C37: NATURAL SCIENCES
C38: Biology | D38: 20 | E38: INT WIS | F38: =INT -> 14 | G38: =WIS -> 4 | J38: =IF(AND(D38 < 4, D38 > 1)," Coin", IF(AND(D38 < 20, D38 > 12)," d12", IF(D38 = 0, "No Skill", IF(D38 = 1, 1, " d" & 2*ROUNDDOWN(D38/2,0))))) & IF(I38>0,"+"&I38,I38) -> d20 | K38: =MIN(F38,G38,H38) -> 4 | L38: =D38+I38 -> 20 | M38: NO
C39: Geoscience | D39: 18 | E39: INT WIS | F39: =INT -> 14 | G39: =WIS -> 4 | J39: =IF(AND(D39 < 4, D39 > 1)," Coin", IF(AND(D39 < 20, D39 > 12)," d12", IF(D39 = 0, "No Skill", IF(D39 = 1, 1, " d" & 2*ROUNDDOWN(D39/2,0))))) & IF(I39>0,"+"&I39,I39) -> d12 | K39: =MIN(F39,G39,H39) -> 4 | L39: =D39+I39 -> 18 | M39: NO
C40: Chemistry | D40: 14 | E40: INT WIS | F40: =INT -> 14 | G40: =WIS -> 4 | J40: =IF(AND(D40 < 4, D40 > 1)," Coin", IF(AND(D40 < 20, D40 > 12)," d12", IF(D40 = 0, "No Skill", IF(D40 = 1, 1, " d" & 2*ROUNDDOWN(D40/2,0))))) & IF(I40>0,"+"&I40,I40) -> d12 | K40: =MIN(F40,G40,H40) -> 4 | L40: =D40+I40 -> 14 | M40: NO
C41: Physics | D41: 20 | E41: INT WIS | F41: =INT -> 14 | G41: =WIS -> 4 | J41: =IF(AND(D41 < 4, D41 > 1)," Coin", IF(AND(D41 < 20, D41 > 12)," d12", IF(D41 = 0, "No Skill", IF(D41 = 1, 1, " d" & 2*ROUNDDOWN(D41/2,0))))) & IF(I41>0,"+"&I41,I41) -> d20 | K41: =MIN(F41,G41,H41) -> 4 | L41: =D41+I41 -> 20 | M41: NO
...

Sheet Inventory
B1: Inventory
B2: SORT | C2: NAME | D2: GRADE | E2: CLASS | F2: MATERIAL | G2: DAMAGE | O2: RANGE | P2: RESISTS | V2: DESCRIPTION & MODS | AG2: VALUE | AH2: CONDITION | AI2: WEIGHT
G3: PIERCING | H3: BASHING | I3: SLASHING | K3: FIRE | L3: COLD | M3: ELECTRIC | N3: ACID | P3: RATING | Q3: TYPE | R3: FIRE | S3: COLD | T3: ELECTRIC | U3: ACID | W3: HEAD | X3: CHEST | Y3: ULARM | Z3: URARM | AA3: LLARM | AB3: LRARM | AC3: ULLEG | AD3: URLEG | AE3: LLLEG | AF3: LRLEG
B4: 1 | C4: Robes of the Magna | D4: 5 - Mythical | E4: Clothing | F4: Silk | J4: : | P4: 14 | Q4: Soft | V4: Grants +2 to all pillars of magic. All beneficial magic has a -5 DR while all adversarial magic targetting you has a +5 DR , Indestructible | W4: FALSE | X4: TRUE | Y4: TRUE | Z4: TRUE | AA4: TRUE | AB4: TRUE | AC4: TRUE | AD4: TRUE | AE4: FALSE | AF4: FALSE | AG4: 10 - Priceless | AH4: 4- Indestructible | AI4: 1.98 | AJ4: =IFERROR(__xludf.DUMMYFUNCTION("IF(E4=""Heavy Armor"",IF(REGEXMATCH(V4,""Flexible""),""0"",COUNTIF(W4:AF4,true)),)"),"")
B5: 2 | C5: Mask of the Magna | D5: 5 - Mythical | E5: Clothing | F5: Adamant | J5: : | P5: 33 | Q5: Hard | V5: Allows casting of "Mind Blank" once per day. Indestructible | W5: TRUE | X5: FALSE | Y5: FALSE | Z5: FALSE | AA5: FALSE | AB5: FALSE | AC5: FALSE | AD5: FALSE | AE5: FALSE | AF5: FALSE | AG5: 10 - Priceless | AH5: 4- Indestructible | AI5: 0.16 | AJ5: =IFERROR(__xludf.DUMMYFUNCTION("IF(E5=""Heavy Armor"",IF(REGEXMATCH(V5,""Flexible""),""0"",COUNTIF(W5:AF5,true)),)"),"")
B6: 3 | C6: Ring of Telekinesis | D6: 4 - Noble | E6: Other | F6: Silver | J6: : | P6: 17 | Q6: Hard | V6: Allows casting of "telekinesis" targetting unworn or uncarried objects. | W6: FALSE | X6: FALSE | Y6: FALSE | Z6: FALSE | AA6: FALSE | AB6: FALSE | AC6: FALSE | AD6: FALSE | AE6: FALSE | AF6: FALSE | AG6: 7 - Costly | AH6: 3 - Undamaged | AI6: 0.01 | AJ6: =IFERROR(__xludf.DUMMYFUNCTION("IF(E6=""Heavy Armor"",IF(REGEXMATCH(V6,""Flexible""),""0"",COUNTIF(W6:AF6,true)),)"),"")
B7: 4 | C7: Manabot Interface MkXVI | D7: 4 - Noble | E7: Catalyst | F7: Graphene | J7: : | P7: 45 | Q7: Soft | V7: Equivalent to MkV Nano Interface. Partial Supression of Strange Vibrations. Memory 20. Mana 40. Force:15 . +2 to all Save Mods. Immune to magic. | W7: FALSE | X7: FALSE | Y7: FALSE | Z7: FALSE | AA7: FALSE | AB7: FALSE | AC7: FALSE | AD7: FALSE | AE7: FALSE | AF7: FALSE | AG7: 10 - Priceless | AH7: 3 - Undamaged | AI7: 0 | AJ7: =IFERROR(__xludf.DUMMYFUNCTION("IF(E7=""Heavy Armor"",IF(REGEXMATCH(V7,""Flexible""),""0"",COUNTIF(W7:AF7,true)),)"),"")
B8: 5 | C8: Leather Boot (L) | D8: 3 - Munitions | E8: Clothing | F8: Leather | G8: - | H8: - | I8: - | J8: : | K8: - | L8: - | M8: - | N8: - | O8: - | P8: 8 | Q8: Soft | R8: R | V8: Hard to Repair | W8: FALSE | X8: FALSE | Y8: FALSE | Z8: FALSE | AA8: FALSE | AB8: FALSE | AC8: FALSE | AD8: FALSE | AE8: TRUE | AF8: FALSE | AG8: 4 - Inexpensive | AH8: 3 - Undamaged | AI8: 1.43 | AJ8: =IFERROR(__xludf.DUMMYFUNCTION("IF(E8=""Heavy Armor"",IF(REGEXMATCH(V8,""Flexible""),""0"",COUNTIF(W8:AF8,true)),)"),"")
B9: 6 | C9: Leather Boot (R) | D9: 3 - Munitions | E9: Clothing | F9: Leather | G9: - | H9: - | I9: - | J9: : | K9: - | L9: - | M9: - | N9: - | O9: - | P9: 8 | Q9: Soft | R9: R | V9: Hard to Repair | W9: FALSE | X9: FALSE | Y9: FALSE | Z9: FALSE | AA9: FALSE | AB9: FALSE | AC9: FALSE | AD9: FALSE | AE9: FALSE | AF9: TRUE | AG9: 4 - Inexpensive | AH9: 3 - Undamaged | AI9: 1.43 | AJ9: =IFERROR(__xludf.DUMMYFUNCTION("IF(E9=""Heavy Armor"",IF(REGEXMATCH(V9,""Flexible""),""0"",COUNTIF(W9:AF9,true)),)"),"")
B10: 7 | C10: Energy Shield | D10: 3 - Munitions | E10: Heavy Armor | J10: : | P10: 80 | Q10: Hard | R10: P | T10: P | U10: P | V10: Immune to fire, electricity, and acid. | W10: FALSE | X10: FALSE | Y10: FALSE | Z10: TRUE | AA10: FALSE | AB10: TRUE | AC10: FALSE | AD10: FALSE | AE10: FALSE | AF10: FALSE | AJ10: =IFERROR(__xludf.DUMMYFUNCTION("IF(E10=""Heavy Armor"",IF(REGEXMATCH(V10,""Flexible""),""0"",COUNTIF(W10:AF10,true)),)"),2.0) -> 2
B11: 8 | C11: Teru's Gift | D11: 4 - Noble | E11: One-Handed Weapon | F11: Steel | G11: 60 | H11: 30 | I11: 0 | J11: : | K11: 0 | L11: 0 | M11: 0 | N11: 0 | O11: 40 ft | P11: 23 | Q11: Hard | V11: Quick Reload | W11: FALSE | X11: FALSE | Y11: FALSE | Z11: FALSE | AA11: FALSE | AB11: FALSE | AC11: FALSE | AD11: FALSE | AE11: FALSE | AF11: FALSE | AG11: 8 - Valuable | AH11: 3 - Undamaged | AI11: 0.5 | AJ11: =IFERROR(__xludf.DUMMYFUNCTION("IF(E11=""Heavy Armor"",IF(REGEXMATCH(V11,""Flexible""),""0"",COUNTIF(W11:AF11,true)),)"),"")
B12: 9 | C12: Flak Vest | D12: 3 - Munitions | E12: Light Armor | F12: Carbon Fiber | J12: : | P12: 42 | Q12: Hard | V12: Brittle | W12: FALSE | X12: TRUE | Y12: FALSE | Z12: FALSE | AA12: FALSE | AB12: FALSE | AC12: FALSE | AD12: FALSE | AE12: FALSE | AF12: FALSE | AG12: 7 - Costly | AH12: 3 - Undamaged | AI12: 5.2 | AJ12: =IFERROR(__xludf.DUMMYFUNCTION("IF(E12=""Heavy Armor"",IF(REGEXMATCH(V12,""Flexible""),""0"",COUNTIF(W12:AF12,true)),)"),"")
B13: 10 | C13: P.R.A. | D13: 3 - Munitions | E13: Clothing | F13: Force | J13: : | P13: 50 | Q13: Hard | V13: Brittle | W13: TRUE | X13: TRUE | Y13: TRUE | Z13: TRUE | AA13: TRUE | AB13: TRUE | AC13: TRUE | AD13: TRUE | AE13: TRUE | AF13: TRUE | AJ13: =IFERROR(__xludf.DUMMYFUNCTION("IF(E13=""Heavy Armor"",IF(REGEXMATCH(V13,""Flexible""),""0"",COUNTIF(W13:AF13,true)),)"),"")
B14: 11 | C14: 10 of swords | J14: : | W14: FALSE | X14: FALSE | Y14: FALSE | Z14: FALSE | AA14: FALSE | AB14: FALSE | AC14: FALSE | AD14: FALSE | AE14: FALSE | AF14: FALSE | AJ14: =IFERROR(__xludf.DUMMYFUNCTION("IF(E14=""Heavy Armor"",IF(REGEXMATCH(V14,""Flexible""),""0"",COUNTIF(W14:AF14,true)),)"),"")
B15: 12 | C15: 2 of chalices | J15: : | W15: FALSE | X15: FALSE | Y15: FALSE | Z15: FALSE | AA15: FALSE | AB15: FALSE | AC15: FALSE | AD15: FALSE | AE15: FALSE | AF15: FALSE | AJ15: =IFERROR(__xludf.DUMMYFUNCTION("IF(E15=""Heavy Armor"",IF(REGEXMATCH(V15,""Flexible""),""0"",COUNTIF(W15:AF15,true)),)"),"")
B16: 13 | C16: Ace of Swords | J16: : | W16: FALSE | X16: FALSE | Y16: FALSE | Z16: FALSE | AA16: FALSE | AB16: FALSE | AC16: FALSE | AD16: FALSE | AE16: FALSE | AF16: FALSE | AJ16: =IFERROR(__xludf.DUMMYFUNCTION("IF(E16=""Heavy Armor"",IF(REGEXMATCH(V16,""Flexible""),""0"",COUNTIF(W16:AF16,true)),)"),"")
B17: 14 | C17: Time Pearl | J17: : | W17: FALSE | X17: FALSE | Y17: FALSE | Z17: FALSE | AA17: FALSE | AB17: FALSE | AC17: FALSE | AD17: FALSE | AE17: FALSE | AF17: FALSE | AJ17: =IFERROR(__xludf.DUMMYFUNCTION("IF(E17=""Heavy Armor"",IF(REGEXMATCH(V17,""Flexible""),""0"",COUNTIF(W17:AF17,true)),)"),"")
B18: 15 | C18: God tools | J18: : | W18: FALSE | X18: FALSE | Y18: FALSE | Z18: FALSE | AA18: FALSE | AB18: FALSE | AC18: FALSE | AD18: FALSE | AE18: FALSE | AF18: FALSE | AJ18: =IFERROR(__xludf.DUMMYFUNCTION("IF(E18=""Heavy Armor"",IF(REGEXMATCH(V18,""Flexible""),""0"",COUNTIF(W18:AF18,true)),)"),"")
B19: 16 | C19: Wheel of fortune | J19: : | W19: FALSE | X19: FALSE | Y19: FALSE | Z19: FALSE | AA19: FALSE | AB19: FALSE | AC19: FALSE | AD19: FALSE | AE19: FALSE | AF19: FALSE | AJ19: =IFERROR(__xludf.DUMMYFUNCTION("IF(E19=""Heavy Armor"",IF(REGEXMATCH(V19,""Flexible""),""0"",COUNTIF(W19:AF19,true)),)"),"")
B20: 17 | C20: Death | J20: : | V20: Death defy- dwell | W20: FALSE | X20: FALSE | Y20: FALSE | Z20: FALSE | AA20: FALSE | AB20: FALSE | AC20: FALSE | AD20: FALSE | AE20: FALSE | AF20: FALSE | AJ20: =IFERROR(__xludf.DUMMYFUNCTION("IF(E20=""Heavy Armor"",IF(REGEXMATCH(V20,""Flexible""),""0"",COUNTIF(W20:AF20,true)),)"),"")
B21: 18 | C21: Unstable perfect materia | J21: : | W21: FALSE | X21: FALSE | Y21: FALSE | Z21: FALSE | AA21: FALSE | AB21: FALSE | AC21: FALSE | AD21: FALSE | AE21: FALSE | AF21: FALSE | AJ21: =IFERROR(__xludf.DUMMYFUNCTION("IF(E21=""Heavy Armor"",IF(REGEXMATCH(V21,""Flexible""),""0"",COUNTIF(W21:AF21,true)),)"),"")
B22: 19 | J22: : | W22: FALSE | X22: FALSE | Y22: FALSE | Z22: FALSE | AA22: FALSE | AB22: FALSE | AC22: FALSE | AD22: FALSE | AE22: FALSE | AF22: FALSE | AJ22: =IFERROR(__xludf.DUMMYFUNCTION("IF(E22=""Heavy Armor"",IF(REGEXMATCH(V22,""Flexible""),""0"",COUNTIF(W22:AF22,true)),)"),"")
B23: 20 | J23: : | W23: FALSE | X23: FALSE | Y23: FALSE | Z23: FALSE | AA23: FALSE | AB23: FALSE | AC23: FALSE | AD23: FALSE | AE23: FALSE | AF23: FALSE | AJ23: =IFERROR(__xludf.DUMMYFUNCTION("IF(E23=""Heavy Armor"",IF(REGEXMATCH(V23,""Flexible""),""0"",COUNTIF(W23:AF23,true)),)"),"")
B24: 21 | J24: : | W24: FALSE | X24: FALSE | Y24: FALSE | Z24: FALSE | AA24: FALSE | AB24: FALSE | AC24: FALSE | AD24: FALSE | AE24: FALSE | AF24: FALSE | AJ24: =IFERROR(__xludf.DUMMYFUNCTION("IF(E24=""Heavy Armor"",IF(REGEXMATCH(V24,""Flexible""),""0"",COUNTIF(W24:AF24,true)),)"),"")
B25: 22 | J25: : | W25: FALSE | X25: FALSE | Y25: FALSE | Z25: FALSE | AA25: FALSE | AB25: FALSE | AC25: FALSE | AD25: FALSE | AE25: FALSE | AF25: FALSE | AJ25: =IFERROR(__xludf.DUMMYFUNCTION("IF(E25=""Heavy Armor"",IF(REGEXMATCH(V25,""Flexible""),""0"",COUNTIF(W25:AF25,true)),)"),"")
B26: 23 | J26: : | W26: FALSE | X26: FALSE | Y26: FALSE | Z26: FALSE | AA26: FALSE | AB26: FALSE | AC26: FALSE | AD26: FALSE | AE26: FALSE | AF26: FALSE | AJ26: =IFERROR(__xludf.DUMMYFUNCTION("IF(E26=""Heavy Armor"",IF(REGEXMATCH(V26,""Flexible""),""0"",COUNTIF(W26:AF26,true)),)"),"")
B27: 24 | J27: : | W27: FALSE | X27: FALSE | Y27: FALSE | Z27: FALSE | AA27: FALSE | AB27: FALSE | AC27: FALSE | AD27: FALSE | AE27: FALSE | AF27: FALSE | AJ27: =IFERROR(__xludf.DUMMYFUNCTION("IF(E27=""Heavy Armor"",IF(REGEXMATCH(V27,""Flexible""),""0"",COUNTIF(W27:AF27,true)),)"),"")
B28: 25 | J28: : | W28: FALSE | X28: FALSE | Y28: FALSE | Z28: FALSE | AA28: FALSE | AB28: FALSE | AC28: FALSE | AD28: FALSE | AE28: FALSE | AF28: FALSE | AJ28: =IFERROR(__xludf.DUMMYFUNCTION("IF(E28=""Heavy Armor"",IF(REGEXMATCH(V28,""Flexible""),""0"",COUNTIF(W28:AF28,true)),)"),"")
B29: 26 | J29: : | W29: FALSE | X29: FALSE | Y29: FALSE | Z29: FALSE | AA29: FALSE | AB29: FALSE | AC29: FALSE | AD29: FALSE | AE29: FALSE | AF29: FALSE | AJ29: =IFERROR(__xludf.DUMMYFUNCTION("IF(E29=""Heavy Armor"",IF(REGEXMATCH(V29,""Flexible""),""0"",COUNTIF(W29:AF29,true)),)"),"")
B30: 27 | J30: : | W30: FALSE | X30: FALSE | Y30: FALSE | Z30: FALSE | AA30: FALSE | AB30: FALSE | AC30: FALSE | AD30: FALSE | AE30: FALSE | AF30: FALSE | AJ30: =IFERROR(__xludf.DUMMYFUNCTION("IF(E30=""Heavy Armor"",IF(REGEXMATCH(V30,""Flexible""),""0"",COUNTIF(W30:AF30,true)),)"),"")
B31: 28 | J31: : | W31: FALSE | X31: FALSE | Y31: FALSE | Z31: FALSE | AA31: FALSE | AB31: FALSE | AC31: FALSE | AD31: FALSE | AE31: FALSE | AF31: FALSE | AJ31: =IFERROR(__xludf.DUMMYFUNCTION("IF(E31=""Heavy Armor"",IF(REGEXMATCH(V31,""Flexible""),""0"",COUNTIF(W31:AF31,true)),)"),"")
B32: 29 | J32: : | W32: FALSE | X32: FALSE | Y32: FALSE | Z32: FALSE | AA32: FALSE | AB32: FALSE | AC32: FALSE | AD32: FALSE | AE32: FALSE | AF32: FALSE | AJ32: =IFERROR(__xludf.DUMMYFUNCTION("IF(E32=""Heavy Armor"",IF(REGEXMATCH(V32,""Flexible""),""0"",COUNTIF(W32:AF32,true)),)"),"")
B33: 30 | J33: : | W33: FALSE | X33: FALSE | Y33: FALSE | Z33: FALSE | AA33: FALSE | AB33: FALSE | AC33: FALSE | AD33: FALSE | AE33: FALSE | AF33: FALSE | AJ33: =IFERROR(__xludf.DUMMYFUNCTION("IF(E33=""Heavy Armor"",IF(REGEXMATCH(V33,""Flexible""),""0"",COUNTIF(W33:AF33,true)),)"),"")
B34: 31 | J34: : | W34: FALSE | X34: FALSE | Y34: FALSE | Z34: FALSE | AA34: FALSE | AB34: FALSE | AC34: FALSE | AD34: FALSE | AE34: FALSE | AF34: FALSE | AJ34: =IFERROR(__xludf.DUMMYFUNCTION("IF(E34=""Heavy Armor"",IF(REGEXMATCH(V34,""Flexible""),""0"",COUNTIF(W34:AF34,true)),)"),"")
B35: 32 | C35: Jude's Special EM Plasma Round | D35: 5 - Mythical | E35: Other | G35: 20 | H35: 80 | I35: 0 | J35: : | K35: 40 | L35: 0 | M35: 0 | N35: 0 | O35: - | P35: 20 | Q35: Hard | V35: Ammo for Jude's Gun | W35: FALSE | X35: FALSE | Y35: FALSE | Z35: FALSE | AA35: FALSE | AB35: FALSE | AC35: FALSE | AD35: FALSE | AE35: FALSE | AF35: FALSE | AG35: 9 - Extravagant | AH35: 3 - Substantial | AI35: 2 | AJ35: =IFERROR(__xludf.DUMMYFUNCTION("IF(E35=""Heavy Armor"",IF(REGEXMATCH(V35,""Flexible""),""0"",COUNTIF(W35:AF35,true)),)"),"")
B36: 33 | C36: Electric Plasma Round | D36: 5 - Mythical | E36: Other | G36: 0 | H36: 0 | I36: 0 | J36: : | K36: 0 | L36: 0 | M36: 200 | N36: 0 | O36: - | P36: 20 | Q36: Hard | V36: Ammo for Jude's Gun | W36: FALSE | X36: FALSE | Y36: FALSE | Z36: FALSE | AA36: FALSE | AB36: FALSE | AC36: FALSE | AD36: FALSE | AE36: FALSE | AF36: FALSE | AG36: 9 - Extravagant | AH36: 3 - Substantial | AI36: 2 | AJ36: =IFERROR(__xludf.DUMMYFUNCTION("IF(E36=""Heavy Armor"",IF(REGEXMATCH(V36,""Flexible""),""0"",COUNTIF(W36:AF36,true)),)"),"")
B37: 34 | C37: Jude's EM Revolver | D37: 5 - Mythical | E37: One-Handed Weapon | F37: Carbon Fiber Advanced Weave | G37: 20 | H37: 30 | I37: 0 | J37: : | K37: 0 | L37: 0 | M37: 0 | N37: 0 | O37: 60 | P37: 80 | Q37: Hard | V37: Electric Magnet revolver, 8 Chambers; Unbreakable, Unblockable; 3 Basic Actions to fully reload (1 per 3 chambers) | W37: FALSE | X37: FALSE | Y37: FALSE | Z37: FALSE | AA37: FALSE | AB37: FALSE | AC37: FALSE | AD37: FALSE | AE37: FALSE | AF37: FALSE | AG37: 10 - Priceless | AH37: 4- Indestructible | AI37: 4.4 | AJ37: =IFERROR(__xludf.DUMMYFUNCTION("IF(E37=""Heavy Armor"",IF(REGEXMATCH(V37,""Flexible""),""0"",COUNTIF(W37:AF37,true)),)"),"")
C38: Leather Boot | AH38: TOTAL WEIGHT | AI38: =SUMPRODUCT(AI4:AI37) -> 19.11

Sheet SEEDDATA
A1: =IFERROR(__xludf.DUMMYFUNCTION("QUERY(IMPORTRANGE(""1LSZsvd5srg8btBs9sLMdlzhljmYMjfhdQyDyeo88BTk"",""Seeds!$B$3:$B""),""select Col1 where Col1 is not null AND NOT Col1 contains '['"",0)"),"Human") -> Human | B1: =IFERROR(__xludf.DUMMYFUNCTION("QUERY(IMPORTRANGE(""1LSZsvd5srg8btBs9sLMdlzhljmYMjfhdQyDyeo88BTk"",""Seeds!$C$3:$C""),""select Col1 where Col1 is not null AND NOT Col1 contains '['"",0)"),30.0) -> 30
A2: =IFERROR(__xludf.DUMMYFUNCTION("""COMPUTED_VALUE"""),"Altered Human") -> Altered Human | B2: =IFERROR(__xludf.DUMMYFUNCTION("""COMPUTED_VALUE"""),63.0) -> 63
A3: =IFERROR(__xludf.DUMMYFUNCTION("""COMPUTED_VALUE"""),"Neo-Human") -> Neo-Human | B3: =IFERROR(__xludf.DUMMYFUNCTION("""COMPUTED_VALUE"""),145.0) -> 145
A4: =IFERROR(__xludf.DUMMYFUNCTION("""COMPUTED_VALUE"""),"Elven") -> Elven | B4: =IFERROR(__xludf.DUMMYFUNCTION("""COMPUTED_VALUE"""),78.0) -> 78
A5: =IFERROR(__xludf.DUMMYFUNCTION("""COMPUTED_VALUE"""),"Dwarven") -> Dwarven | B5: =IFERROR(__xludf.DUMMYFUNCTION("""COMPUTED_VALUE"""),78.0) -> 78
A6: =IFERROR(__xludf.DUMMYFUNCTION("""COMPUTED_VALUE"""),"Halfling") -> Halfling | B6: =IFERROR(__xludf.DUMMYFUNCTION("""COMPUTED_VALUE"""),48.0) -> 48
A7: =IFERROR(__xludf.DUMMYFUNCTION("""COMPUTED_VALUE"""),"*Draconic") -> *Draconic | B7: =IFERROR(__xludf.DUMMYFUNCTION("""COMPUTED_VALUE"""),130.0) -> 130
A8: =IFERROR(__xludf.DUMMYFUNCTION("""COMPUTED_VALUE"""),"Tulpa") -> Tulpa | B8: =IFERROR(__xludf.DUMMYFUNCTION("""COMPUTED_VALUE"""),63.0) -> 63
A9: =IFERROR(__xludf.DUMMYFUNCTION("""COMPUTED_VALUE"""),"Homunculus") -> Homunculus | B9: =IFERROR(__xludf.DUMMYFUNCTION("""COMPUTED_VALUE"""),92.0) -> 92
A10: =IFERROR(__xludf.DUMMYFUNCTION("""COMPUTED_VALUE"""),"Cambion") -> Cambion | B10: =IFERROR(__xludf.DUMMYFUNCTION("""COMPUTED_VALUE"""),70.0) -> 70
A11: =IFERROR(__xludf.DUMMYFUNCTION("""COMPUTED_VALUE"""),"Moroi") -> Moroi | B11: =IFERROR(__xludf.DUMMYFUNCTION("""COMPUTED_VALUE"""),96.0) -> 96
A12: =IFERROR(__xludf.DUMMYFUNCTION("""COMPUTED_VALUE"""),"Nephilim") -> Nephilim | B12: =IFERROR(__xludf.DUMMYFUNCTION("""COMPUTED_VALUE"""),73.0) -> 73
A13: =IFERROR(__xludf.DUMMYFUNCTION("""COMPUTED_VALUE"""),"*Cyborg") -> *Cyborg | B13: =IFERROR(__xludf.DUMMYFUNCTION("""COMPUTED_VALUE"""),132.0) -> 132
A14: =IFERROR(__xludf.DUMMYFUNCTION("""COMPUTED_VALUE"""),"*Android") -> *Android
A15: =IFERROR(__xludf.DUMMYFUNCTION("""COMPUTED_VALUE"""),"*Tin Man") -> *Tin Man
A16: =IFERROR(__xludf.DUMMYFUNCTION("""COMPUTED_VALUE"""),"*Beta (The Forgotten Ones)") -> *Beta (The Forgotten Ones)
A17: =IFERROR(__xludf.DUMMYFUNCTION("""COMPUTED_VALUE"""),"*Turbaraptus (The Wretched)") -> *Turbaraptus (The Wretched)

Sheet Vitals
A1: Vitals
E3: Undamaged | Q3: =IFERROR(IF(vlookup(O22,Inventory!C4:AF37,21,false)=TRUE, IF(V22="Destroyed",0,IF(V22="Broken",ROUNDUP(vlookup(O22,Inventory!C4:AF37,14,false)/2,0) & " " & vlookup(O22,Inventory!C4:AF37,15,false),vlookup(O22,Inventory!C4:AF37,14,false) & " " & vlookup(O22,Inventory!C4:AF37,15,false))), IFERROR(IF(vlookup(O23,Inventory!C4:AF37,21,false)=TRUE, IF(V23="Destroyed",0,IF(V23="Broken",ROUNDUP(vlookup(O23,Inventory!C4:AF37,14,false)/2,0) & " " & vlookup(O23,Inventory!C4:Q37,15,false),vlookup(O23,Inventory!C4:AF37,14,false) & " " & vlookup(O23,Inventory!C4:AF37,15,false))), IFERROR(IF(vlookup(O24,Inventory!C4:AF37,21,false)=TRUE, IF(V24="Destroyed",0,IF(V24="Broken",ROUNDUP(vlookup(O24,Inventory!C4:AF37,14,false)/2,0) & " " & vlookup(O24,Inventory!C4:Q37,15,false),vlookup(O24,Inventory!C4:AF37,14,false) & " " & vlookup(O24,Inventory!C4:AF37,15,false))), IFERROR(IF(vlookup(O25,Inventory!C4:AF37,21,false)=TRUE, IF(V25="Destroyed",0,IF(V25="Broken",ROUNDUP(vlookup(O25,Inventory!C4:AF37,14,false)/2,0) & " " & vlookup(O25,Inventory!C4:Q37,15,false),vlookup(O25,Inventory!C4:AF37,14,false) & " " & vlookup(O25,Inventory!C4:AF37,15,false))), IFERROR(IF(vlookup(O26,Inventory!C4:AF37,21,false)=TRUE, IF(V26="Destroyed",0,IF(V26="Broken",ROUNDUP(vlookup(O26,Inventory!C4:AF37,14,false)/2,0) & " " & vlookup(O26,Inventory!C4:Q37,15,false),vlookup(O26,Inventory!C4:AF37,14,false) & " " & vlookup(O26,Inventory!C4:AF37,15,false))), IFERROR(IF(vlookup(O27,Inventory!C4:AF37,21,false)=TRUE, IF(V27="Destroyed",0,IF(V27="Broken",ROUNDUP(vlookup(O27,Inventory!C4:AF37,14,false)/2,0) & " " & vlookup(O27,Inventory!C4:Q37,15,false),vlookup(O27,Inventory!C4:AF37,14,false) & " " & vlookup(O27,Inventory!C4:AF37,15,false))), IFERROR(IF(vlookup(O28,Inventory!C4:AF37,21,false)=TRUE, IF(V28="Destroyed",0,IF(V28="Broken",ROUNDUP(vlookup(O28,Inventory!C4:AF37,14,false)/2,0) & " " & vlookup(O28,Inventory!C4:Q37,15,false),vlookup(O28,Inventory!C4:AF37,14,false) & " " & vlookup(O28,Inventory!C4:AF37,15,false))), IFERROR(IF(vlookup(O29,Inventory!C4:AF37,21,false)=TRUE, IF(V29="Destroyed",0,IF(V29="Broken",ROUNDUP(vlookup(O29,Inventory!C4:AF37,14,false)/2,0) & " " & vlookup(O29,Inventory!C4:Q37,15,false),vlookup(O29,Inventory!C4:AF37,14,false) & " " & vlookup(O29,Inventory!C4:AF37,15,false))), IFERROR(IF(vlookup(O30,Inventory!C4:AF37,21,false)=TRUE, IF(V30="Destroyed",0,IF(V30="Broken",ROUNDUP(vlookup(O30,Inventory!C4:AF37,14,false)/2,0) & " " & vlookup(O30,Inventory!C4:Q37,15,false),vlookup(O30,Inventory!C4:AF37,14,false) & " " & vlookup(O30,Inventory!C4:Q37,15,false))), IFERROR(IF(vlookup(O31,Inventory!C4:AF37,21,false)=TRUE, IF(V31="Destroyed",0,IF(V31="Broken",ROUNDUP(vlookup(O31,Inventory!C4:AF37,14,false)/2,0) & " " & vlookup(O31,Inventory!C4:Q37,15,false),vlookup(O31,Inventory!C4:AF37,14,false) & " " & vlookup(O31,Inventory!C4:Q37,15,false)))),"")),"")),"")),"")),"") ),"")),"")),"")),"")),"") -> 33 Hard | AK3: =IFERROR(IF(vlookup(AI22,Inventory!C4:AF37,21,false)=TRUE, IF(AP22="Destroyed",0,IF(AP22="Broken",ROUNDUP(vlookup(AI22,Inventory!C4:AF37,14,false)/2,0) & " " & vlookup(AI22,Inventory!C4:AF37,15,false),vlookup(AI22,Inventory!C4:AF37,14,false) & " " & vlookup(AI22,Inventory!C4:AF37,15,false))), IFERROR(IF(vlookup(AI23,Inventory!C4:AF37,21,false)=TRUE, IF(AP23="Destroyed",0,IF(AP23="Broken",ROUNDUP(vlookup(AI23,Inventory!C4:AF37,14,false)/2,0) & " " & vlookup(AI23,Inventory!C4:Q37,15,false),vlookup(AI23,Inventory!C4:AF37,14,false) & " " & vlookup(AI23,Inventory!C4:AF37,15,false))), IFERROR(IF(vlookup(AI24,Inventory!C4:AF37,21,false)=TRUE, IF(AP24="Destroyed",0,IF(AP24="Broken",ROUNDUP(vlookup(AI24,Inventory!C4:AF37,14,false)/2,0) & " " & vlookup(AI24,Inventory!C4:Q37,15,false),vlookup(AI24,Inventory!C4:AF37,14,false) & " " & vlookup(AI24,Inventory!C4:AF37,15,false))), IFERROR(IF(vlookup(AI25,Inventory!C4:AF37,21,false)=TRUE, IF(AP25="Destroyed",0,IF(AP25="Broken",ROUNDUP(vlookup(AI25,Inventory!C4:AF37,14,false)/2,0) & " " & vlookup(AI25,Inventory!C4:Q37,15,false),vlookup(AI25,Inventory!C4:AF37,14,false) & " " & vlookup(AI25,Inventory!C4:AF37,15,false))), IFERROR(IF(vlookup(AI26,Inventory!C4:AF37,21,false)=TRUE, IF(AP26="Destroyed",0,IF(AP26="Broken",ROUNDUP(vlookup(AI26,Inventory!C4:AF37,14,false)/2,0) & " " & vlookup(AI26,Inventory!C4:Q37,15,false),vlookup(AI26,Inventory!C4:AF37,14,false) & " " & vlookup(AI26,Inventory!C4:AF37,15,false))), IFERROR(IF(vlookup(AI27,Inventory!C4:AF37,21,false)=TRUE, IF(AP27="Destroyed",0,IF(AP27="Broken",ROUNDUP(vlookup(AI27,Inventory!C4:AF37,14,false)/2,0) & " " & vlookup(AI27,Inventory!C4:Q37,15,false),vlookup(AI27,Inventory!C4:AF37,14,false) & " " & vlookup(AI27,Inventory!C4:AF37,15,false))), IFERROR(IF(vlookup(AI28,Inventory!C4:AF37,21,false)=TRUE, IF(AP28="Destroyed",0,IF(AP28="Broken",ROUNDUP(vlookup(AI28,Inventory!C4:AF37,14,false)/2,0) & " " & vlookup(AI28,Inventory!C4:Q37,15,false),vlookup(AI28,Inventory!C4:AF37,14,false) & " " & vlookup(AI28,Inventory!C4:AF37,15,false))), IFERROR(IF(vlookup(AI29,Inventory!C4:AF37,21,false)=TRUE, IF(AP29="Destroyed",0,IF(AP29="Broken",ROUNDUP(vlookup(AI29,Inventory!C4:AF37,14,false)/2,0) & " " & vlookup(AI29,Inventory!C4:Q37,15,false),vlookup(AI29,Inventory!C4:AF37,14,false) & " " & vlookup(AI29,Inventory!C4:AF37,15,false))), IFERROR(IF(vlookup(AI30,Inventory!C4:AF37,21,false)=TRUE, IF(AP30="Destroyed",0,IF(AP30="Broken",ROUNDUP(vlookup(AI30,Inventory!C4:AF37,14,false)/2,0) & " " & vlookup(AI30,Inventory!C4:Q37,15,false),vlookup(AI30,Inventory!C4:AF37,14,false) & " " & vlookup(AI30,Inventory!C4:Q37,15,false))), IFERROR(IF(vlookup(AI31,Inventory!C4:AF37,21,false)=TRUE, IF(AP31="Destroyed",0,IF(AP31="Broken",ROUNDUP(vlookup(AI31,Inventory!C4:AF37,14,false)/2,0) & " " & vlookup(AI31,Inventory!C4:Q37,15,false),vlookup(AI31,Inventory!C4:AF37,14,false) & " " & vlookup(AI31,Inventory!C4:Q37,15,false)))),"")),"")),"")),"")),"") ),"")),"")),"")),"")),"") | BE3: =IFERROR(IF(vlookup(BC22,Inventory!C4:AF37,21,false)=TRUE, IF(BJ22="Destroyed",0,IF(BJ22="Broken",ROUNDUP(vlookup(BC22,Inventory!C4:AF37,14,false)/2,0) & " " & vlookup(BC22,Inventory!C4:AF37,15,false),vlookup(BC22,Inventory!C4:AF37,14,false) & " " & vlookup(BC22,Inventory!C4:AF37,15,false))), IFERROR(IF(vlookup(BC23,Inventory!C4:AF37,21,false)=TRUE, IF(BJ23="Destroyed",0,IF(BJ23="Broken",ROUNDUP(vlookup(BC23,Inventory!C4:AF37,14,false)/2,0) & " " & vlookup(BC23,Inventory!C4:Q37,15,false),vlookup(BC23,Inventory!C4:AF37,14,false) & " " & vlookup(BC23,Inventory!C4:AF37,15,false))), IFERROR(IF(vlookup(BC24,Inventory!C4:AF37,21,false)=TRUE, IF(BJ24="Destroyed",0,IF(BJ24="Broken",ROUNDUP(vlookup(BC24,Inventory!C4:AF37,14,false)/2,0) & " " & vlookup(BC24,Inventory!C4:Q37,15,false),vlookup(BC24,Inventory!C4:AF37,14,false) & " " & vlookup(BC24,Inventory!C4:AF37,15,false))), IFERROR(IF(vlookup(BC25,Inventory!C4:AF37,21,false)=TRUE, IF(BJ25="Destroyed",0,IF(BJ25="Broken",ROUNDUP(vlookup(BC25,Inventory!C4:AF37,14,false)/2,0) & " " & vlookup(BC25,Inventory!C4:Q37,15,false),vlookup(BC25,Inventory!C4:AF37,14,false) & " " & vlookup(BC25,Inventory!C4:AF37,15,false))), IFERROR(IF(vlookup(BC26,Inventory!C4:AF37,21,false)=TRUE, IF(BJ26="Destroyed",0,IF(BJ26="Broken",ROUNDUP(vlookup(BC26,Inventory!C4:AF37,14,false)/2,0) & " " & vlookup(BC26,Inventory!C4:Q37,15,false),vlookup(BC26,Inventory!C4:AF37,14,false) & " " & vlookup(BC26,Inventory!C4:AF37,15,false))), IFERROR(IF(vlookup(BC27,Inventory!C4:AF37,21,false)=TRUE, IF(BJ27="Destroyed",0,IF(BJ27="Broken",ROUNDUP(vlookup(BC27,Inventory!C4:AF37,14,false)/2,0) & " " & vlookup(BC27,Inventory!C4:Q37,15,false),vlookup(BC27,Inventory!C4:AF37,14,false) & " " & vlookup(BC27,Inventory!C4:AF37,15,false))), IFERROR(IF(vlookup(BC28,Inventory!C4:AF37,21,false)=TRUE, IF(BJ28="Destroyed",0,IF(BJ28="Broken",ROUNDUP(vlookup(BC28,Inventory!C4:AF37,14,false)/2,0) & " " & vlookup(BC28,Inventory!C4:Q37,15,false),vlookup(BC28,Inventory!C4:AF37,14,false) & " " & vlookup(BC28,Inventory!C4:AF37,15,false))), IFERROR(IF(vlookup(BC29,Inventory!C4:AF37,21,false)=TRUE, IF(BJ29="Destroyed",0,IF(BJ29="Broken",ROUNDUP(vlookup(BC29,Inventory!C4:AF37,14,false)/2,0) & " " & vlookup(BC29,Inventory!C4:Q37,15,false),vlookup(BC29,Inventory!C4:AF37,14,false) & " " & vlookup(BC29,Inventory!C4:AF37,15,false))), IFERROR(IF(vlookup(BC30,Inventory!C4:AF37,21,false)=TRUE, IF(BJ30="Destroyed",0,IF(BJ30="Broken",ROUNDUP(vlookup(BC30,Inventory!C4:AF37,14,false)/2,0) & " " & vlookup(BC30,Inventory!C4:Q37,15,false),vlookup(BC30,Inventory!C4:AF37,14,false) & " " & vlookup(BC30,Inventory!C4:Q37,15,false))), IFERROR(IF(vlookup(BC31,Inventory!C4:AF37,21,false)=TRUE, IF(BJ31="Destroyed",0,IF(BJ31="Broken",ROUNDUP(vlookup(BC31,Inventory!C4:AF37,14,false)/2,0) & " " & vlookup(BC31,Inventory!C4:Q37,15,false),vlookup(BC31,Inventory!C4:AF37,14,false) & " " & vlookup(BC31,Inventory!C4:Q37,15,false)))),"")),"")),"")),"")),"") ),"")),"")),"")),"")),"")
